Workbook

Sheet BotStuff
A1: Choice State: | B1: {} | Z1: Survey Sent?

Sheet Megadraft​
A1: ARENA GAUNTLET LEAGUE: SOS MEGADRAFT
B3: Rk | C3: Player | D3: Country | E3: Arena ID | F3: Megadraft Record | G3: League Pts (Wins) | H3: Megadraft Round 1 | I3: Megadraft Round 2 | J3: Megadraft Round 3 | K3: Finals Playoffs | L3: Total Points
B4: 1 | C4: Ryan M | D4: USA | E4: rrrn22#32842 | F4: 4 - 0 | G4: 22 | H4: 3 | I4: 3 | J4: 3 | K4: 3 | L4: =SUM(G4:K4) -> 34
B5: 2 | C5: Michael B | D5: USA | E5: Monkeymage#12141 | F5: 3 - 1 | G5: 22 | H5: 3 | I5: 3 | J5: 3 | K5: 0 | L5: =SUM(G5:K5) -> 31
B6: 3 | C6: Nick L | D6: USA | E6: Aliphos#10232 | F6: 2 - 1 | G6: 23 | H6: 3 | I6: 3 | J6: 0 | K6: N/A | L6: =SUM(G6:K6) -> 29
B7: 4 | C7: Wei C | D7: Canada | E7: Azayaka#83352 | F7: 2 - 1 | G7: 21 | H7: 3 | I7: 3 | J7: 0 | K7: N/A | L7: =SUM(G7:K7) -> 27
B8: 5 | C8: Lukas M | D8: USA | E8: Finley_2k1#30925 | F8: 2 - 1 | G8: 21 | H8: 3 | I8: 0 | J8: 3 | K8: N/A | L8: =SUM(G8:K8) -> 27
B9: 6 | C9: Tim O | D9: USA | E9: Zeven28#21705 | F9: 2 - 1 | G9: 21 | H9: 0 | I9: 3 | J9: 3 | K9: N/A | L9: =SUM(G9:K9) -> 27
B10: 7 | C10: Cam B | D10: USA | E10: PrinceEggbert#12155 | F10: 1 - 2 | G10: 23 | H10: 0 | I10: 3 | J10: 0 | K10: N/A | L10: =SUM(G10:K10) -> 26
B11: 8 | C11: Chris O | D11: USA | E11: chriso91#46230 | F11: 2 - 1 | G11: 20 | H11: 3 | I11: 0 | J11: 3 | K11: N/A | L11: =SUM(G11:K11) -> 26
B12: 9 | C12: John P | D12: USA | E12: gokuorgohome#51511 | F12: 2 - 1 | G12: 20 | H12: 0 | I12: 3 | J12: 3 | K12: N/A | L12: =SUM(G12:K12) -> 26
B13: 10 | C13: Theia E | D13: Australia | E13: Catarang#49877 | F13: 1 - 2 | G13: 22 | H13: 3 | I13: 0 | J13: 0 | K13: N/A | L13: =SUM(G13:K13) -> 25
B14: 11 | C14: Chris P | D14: USA | E14: Joker01#66827 | F14: 1 - 2 | G14: 21 | H14: 0 | I14: 3 | J14: 0 | K14: N/A | L14: =SUM(G14:K14) -> 24
B15: 12 | C15: Emmett F | D15: USA | E15: Sepulchure#51526 | F15: 1 - 2 | G15: 21 | H15: 0 | I15: 0 | J15: 3 | K15: N/A | L15: =SUM(G15:K15) -> 24
B16: 13 | C16: Tim W | D16: Germany | E16: zaergaegyr#34014 | F16: 1 - 2 | G16: 21 | H16: 0 | I16: 0 | J16: 3 | K16: N/A | L16: =SUM(G16:K16) -> 24
B17: 14 | C17: Andrew B | D17: USA | E17: azore24#54207 | F17: 1 - 2 | G17: 20 | H17: 3 | I17: 0 | J17: 0 | K17: N/A | L17: =SUM(G17:K17) -> 23
... B19: 16 | C19: Matt G | D19: USA | E19: iluvatar777#20638 | F19: 0 - 3 | G19: 20 | H19: 0 | I19: 0 | J19: 0 | K19: N/A | L19: =SUM(G19:K19) -> 20
C21: MegaDraft 1 | G21: MegaDraft 2
C22: Round 1 | G22: Round 1
C23: Chris O | D23: 2 - 1 | E23: Tim O | G23: Lukas M | I23: 2 - 0 | J23: John P
C24: Nick L | D24: 2 - 0 | E24: Tim W | G24: Ryan M | I24: 2 - 1 | J24: Chris P
C25: Michael B | D25: 2 - 0 | E25: Mike R | G25: Wei C | I25: 2 - 1 | J25: Emmett F
C26: Andrew B | D26: 2 - 0 | E26: Cam B | G26: Theia E | I26: 2 - 1 | J26: Matt G
C28: Round 2 | G28: Round 2
C29: Michael B | D29: 2 - 1 | E29: Chris O | G29: Wei C | I29: 2 - 1 | J29: Lukas M
C30: Nick L | D30: 2 - 0 | E30: Andrew B | G30: Ryan M | I30: 2 - 1 | J30: Theia E
C31: Tim O | D31: 2 - 1 | E31: Mike R | G31: John P | I31: 2 - 1 | J31: Emmett F
C32: Cam B | D32: 2 - 1 | E32: Tim W | G32: Chris P | I32: 2 - 1 | J32: Matt G
C34: Round 3 | G34: Round 3
C35: Michael B | D35: 2 - 0 | E35: Nick L | G35: Ryan M | I35: 2 - 0 | J35: Wei C
C36: Chris O | D36: 2 - 1 | E36: Andrew B | G36: Lukas M | I36: 2 - 1 | J36: Theia E
C37: Tim O | D37: 2 - 1 | E37: Cam B | G37: John P | I37: 2 - 1 | J37: Chris P
C38: Tim W | D38: 2 - 0 | E38: Mike R | G38: Emmett F | I38: 2 - 1 | J38: Matt G
E41: Finals Playoffs
E42: Round 4
E43: Ryan M | F43: 3 - 1 | G43: Michael B

Sheet Standings
A1: ARENA GAUNTLET LEAGUE: Secrets of Strixhaven
A2: Week: | C2: =Quotas!B2 -> 6
A3: PLAYER NAME | B3: ARENA ID | C3: COUNTRY | D3: RANK | E3: Player Name & ID | F3: RECORD | G3: College | H3: MATCHES PLAYED | I3: MATCHES <Min | J3: MATCHES <Max | K3: OMW% | L3: MATCHES TO PLAY STATUS | M3: THIS WEEK | N3: OTHER INFO | O3: wins this week | P3: losses this week | Q3: Time min | R3: Time max
A4: {=XLOOKUP($E4,'Player Database'!$B$2:$B252,'Player Database'!$C$2:$C252)} -> #N/A | B4: {=XLOOKUP($E4,'Player Database'!$B$2:$B252,'Player Database'!$E$2:$E252)} -> #N/A | C4: {=XLOOKUP($E4,'Player Database'!$B$2:$B252,'Player Database'!$F$2:$F252)} -> #N/A | D4: =IFERROR(__xludf.DUMMYFUNCTION("QUERY('Player Database'!A2:B240,""SELECT A,B WHERE B != ' - ' ORDER BY A"")"),1.0) -> 1 | E4: =IFERROR(__xludf.DUMMYFUNCTION("""COMPUTED_VALUE"""),"#REF!") -> #REF! | F4: {=XLOOKUP($E4,'Player Database'!$B$2:$B252,'Player Database'!$K$2:$K252)} -> #N/A | G4: {=XLOOKUP($E4,'Player Database'!$B$2:$B252,'Player Database'!$AE$2:$AE252)} -> #N/A | H4: {=XLOOKUP($E4,'Player Database'!$B$2:$B252,'Player Database'!$H$2:$H252)} -> #N/A | I4: {=XLOOKUP($E4,'Player Database'!$B$2:$B252,'Player Database'!$O$2:$O252)} -> #N/A | J4: {=XLOOKUP($E4,'Player Database'!$B$2:$B252,'Player Database'!$P$2:$P252)} -> #N/A | K4: {=XLOOKUP($E4,'Player Database'!$B$2:$B252,'Player Database'!$U$2:$U252)} -> #N/A | L4: {=XLOOKUP($E4,'Player Database'!$B$2:$B252,'Player Database'!$W$2:$W252)} -> #N/A | M4: =CONCATENATE(O4," - ",P4) -> 0 - 0 | N4: {=IF(XLOOKUP($E4,'Player Database'!$B$2:$B252,'Player Database'!$AA$2:$AA252)="",XLOOKUP($E4,'Player Database'!$B$2:$B252,'Player Database'!$G$2:$G252),XLOOKUP($E4,'Player Database'!$B$2:$B252,'Player Database'!$AA$2:$AA252))} -> #N/A | O4: =COUNTIFs(Matches!$B:$B,E4,Matches!$A:$A,">"&Q4,Matches!$A:$A,"<"&R4) -> 0 | P4: =COUNTIFs(Matches!$C:$C,E4,Matches!$A:$A,">"&Q4,Matches!$A:$A,"<"&R4) -> 0 | Q4: =VLOOKUP($C$2,Quotas!$A$7:$E$14,2,FALSE) -> 46171.708 | R4: =VLOOKUP($C$2,Quotas!$A$7:$E$14,3,FALSE) -> 46178.708
A5: {=XLOOKUP($E5,'Player Database'!$B$2:$B252,'Player Database'!$C$2:$C252)} -> #N/A | B5: {=XLOOKUP($E5,'Player Database'!$B$2:$B252,'Player Database'!$E$2:$E252)} -> #N/A | C5: {=XLOOKUP($E5,'Player Database'!$B$2:$B252,'Player Database'!$F$2:$F252)} -> #N/A | D5: =IFERROR(__xludf.DUMMYFUNCTION("""COMPUTED_VALUE"""),1.0) -> 1 | F5: {=XLOOKUP($E5,'Player Database'!$B$2:$B252,'Player Database'!$K$2:$K252)} -> #N/A | G5: {=XLOOKUP($E5,'Player Database'!$B$2:$B252,'Player Database'!$AE$2:$AE252)} -> #N/A | H5: {=XLOOKUP($E5,'Player Database'!$B$2:$B252,'Player Database'!$H$2:$H252)} -> #N/A | I5: {=XLOOKUP($E5,'Player Database'!$B$2:$B252,'Player Database'!$O$2:$O252)} -> #N/A | J5: {=XLOOKUP($E5,'Player Database'!$B$2:$B252,'Player Database'!$P$2:$P252)} -> #N/A | K5: {=XLOOKUP($E5,'Player Database'!$B$2:$B252,'Player Database'!$U$2:$U252)} -> #N/A | L5: {=XLOOKUP($E5,'Player Database'!$B$2:$B252,'Player Database'!$W$2:$W252)} -> #N/A | M5: =CONCATENATE(O5," - ",P5) -> 0 - 0 | N5: {=IF(XLOOKUP($E5,'Player Database'!$B$2:$B252,'Player Database'!$AA$2:$AA252)="",XLOOKUP($E5,'Player Database'!$B$2:$B252,'Player Database'!$G$2:$G252),XLOOKUP($E5,'Player Database'!$B$2:$B252,'Player Database'!$AA$2:$AA252))} -> #N/A | O5: =COUNTIFs(Matches!$B:$B,E5,Matches!$A:$A,">"&Q5,Matches!$A:$A,"<"&R5) -> 0 | P5: =COUNTIFs(Matches!$C:$C,E5,Matches!$A:$A,">"&Q5,Matches!$A:$A,"<"&R5) -> 0 | Q5: =VLOOKUP($C$2,Quotas!$A$7:$E$14,2,FALSE) -> 46171.708 | R5: =VLOOKUP($C$2,Quotas!$A$7:$E$14,3,FALSE) -> 46178.708
A6: {=XLOOKUP($E6,'Player Database'!$B$2:$B252,'Player Database'!$C$2:$C252)} -> #N/A | B6: {=XLOOKUP($E6,'Player Database'!$B$2:$B252,'Player Database'!$E$2:$E252)} -> #N/A | C6: {=XLOOKUP($E6,'Player Database'!$B$2:$B252,'Player Database'!$F$2:$F252)} -> #N/A | D6: =IFERROR(__xludf.DUMMYFUNCTION("""COMPUTED_VALUE"""),1.0) -> 1 | F6: {=XLOOKUP($E6,'Player Database'!$B$2:$B252,'Player Database'!$K$2:$K252)} -> #N/A | G6: {=XLOOKUP($E6,'Player Database'!$B$2:$B252,'Player Database'!$AE$2:$AE252)} -> #N/A | H6: {=XLOOKUP($E6,'Player Database'!$B$2:$B252,'Player Database'!$H$2:$H252)} -> #N/A | I6: {=XLOOKUP($E6,'Player Database'!$B$2:$B252,'Player Database'!$O$2:$O252)} -> #N/A | J6: {=XLOOKUP($E6,'Player Database'!$B$2:$B252,'Player Database'!$P$2:$P252)} -> #N/A | K6: {=XLOOKUP($E6,'Player Database'!$B$2:$B252,'Player Database'!$U$2:$U252)} -> #N/A | L6: {=XLOOKUP($E6,'Player Database'!$B$2:$B252,'Player Database'!$W$2:$W252)} -> #N/A | M6: =CONCATENATE(O6," - ",P6) -> 0 - 0 | N6: {=IF(XLOOKUP($E6,'Player Database'!$B$2:$B252,'Player Database'!$AA$2:$AA252)="",XLOOKUP($E6,'Player Database'!$B$2:$B252,'Player Database'!$G$2:$G252),XLOOKUP($E6,'Player Database'!$B$2:$B252,'Player Database'!$AA$2:$AA252))} -> #N/A | O6: =COUNTIFs(Matches!$B:$B,E6,Matches!$A:$A,">"&Q6,Matches!$A:$A,"<"&R6) -> 0 | P6: =COUNTIFs(Matches!$C:$C,E6,Matches!$A:$A,">"&Q6,Matches!$A:$A,"<"&R6) -> 0 | Q6: =VLOOKUP($C$2,Quotas!$A$7:$E$14,2,FALSE) -> 46171.708 | R6: =VLOOKUP($C$2,Quotas!$A$7:$E$14,3,FALSE) -> 46178.708
A7: {=XLOOKUP($E7,'Player Database'!$B$2:$B252,'Player Database'!$C$2:$C252)} -> #N/A | B7: {=XLOOKUP($E7,'Player Database'!$B$2:$B252,'Player Database'!$E$2:$E252)} -> #N/A | C7: {=XLOOKUP($E7,'Player Database'!$B$2:$B252,'Player Database'!$F$2:$F252)} -> #N/A | D7: =IFERROR(__xludf.DUMMYFUNCTION("""COMPUTED_VALUE"""),1.0) -> 1 | F7: {=XLOOKUP($E7,'Player Database'!$B$2:$B252,'Player Database'!$K$2:$K252)} -> #N/A | G7: {=XLOOKUP($E7,'Player Database'!$B$2:$B252,'Player Database'!$AE$2:$AE252)} -> #N/A | H7: {=XLOOKUP($E7,'Player Database'!$B$2:$B252,'Player Database'!$H$2:$H252)} -> #N/A | I7: {=XLOOKUP($E7,'Player Database'!$B$2:$B252,'Player Database'!$O$2:$O252)} -> #N/A | J7: {=XLOOKUP($E7,'Player Database'!$B$2:$B252,'Player Database'!$P$2:$P252)} -> #N/A | K7: {=XLOOKUP($E7,'Player Database'!$B$2:$B252,'Player Database'!$U$2:$U252)} -> #N/A | L7: {=XLOOKUP($E7,'Player Database'!$B$2:$B252,'Player Database'!$W$2:$W252)} -> #N/A | M7: =CONCATENATE(O7," - ",P7) -> 0 - 0 | N7: {=IF(XLOOKUP($E7,'Player Database'!$B$2:$B252,'Player Database'!$AA$2:$AA252)="",XLOOKUP($E7,'Player Database'!$B$2:$B252,'Player Database'!$G$2:$G252),XLOOKUP($E7,'Player Database'!$B$2:$B252,'Player Database'!$AA$2:$AA252))} -> #N/A | O7: =COUNTIFs(Matches!$B:$B,E7,Matches!$A:$A,">"&Q7,Matches!$A:$A,"<"&R7) -> 0 | P7: =COUNTIFs(Matches!$C:$C,E7,Matches!$A:$A,">"&Q7,Matches!$A:$A,"<"&R7) -> 0 | Q7: =VLOOKUP($C$2,Quotas!$A$7:$E$14,2,FALSE) -> 46171.708 | R7: =VLOOKUP($C$2,Quotas!$A$7:$E$14,3,FALSE) -> 46178.708
A8: {=XLOOKUP($E8,'Player Database'!$B$2:$B252,'Player Database'!$C$2:$C252)} -> #N/A | B8: {=XLOOKUP($E8,'Player Database'!$B$2:$B252,'Player Database'!$E$2:$E252)} -> #N/A | C8: {=XLOOKUP($E8,'Player Database'!$B$2:$B252,'Player Database'!$F$2:$F252)} -> #N/A | D8: =IFERROR(__xludf.DUMMYFUNCTION("""COMPUTED_VALUE"""),1.0) -> 1 | F8: {=XLOOKUP($E8,'Player Database'!$B$2:$B252,'Player Database'!$K$2:$K252)} -> #N/A | G8: {=XLOOKUP($E8,'Player Database'!$B$2:$B252,'Player Database'!$AE$2:$AE252)} -> #N/A | H8: {=XLOOKUP($E8,'Player Database'!$B$2:$B252,'Player Database'!$H$2:$H252)} -> #N/A | I8: {=XLOOKUP($E8,'Player Database'!$B$2:$B252,'Player Database'!$O$2:$O252)} -> #N/A | J8: {=XLOOKUP($E8,'Player Database'!$B$2:$B252,'Player Database'!$P$2:$P252)} -> #N/A | K8: {=XLOOKUP($E8,'Player Database'!$B$2:$B252,'Player Database'!$U$2:$U252)} -> #N/A | L8: {=XLOOKUP($E8,'Player Database'!$B$2:$B252,'Player Database'!$W$2:$W252)} -> #N/A | M8: =CONCATENATE(O8," - ",P8) -> 0 - 0 | N8: {=IF(XLOOKUP($E8,'Player Database'!$B$2:$B252,'Player Database'!$AA$2:$AA252)="",XLOOKUP($E8,'Player Database'!$B$2:$B252,'Player Database'!$G$2:$G252),XLOOKUP($E8,'Player Database'!$B$2:$B252,'Player Database'!$AA$2:$AA252))} -> #N/A | O8: =COUNTIFs(Matches!$B:$B,E8,Matches!$A:$A,">"&Q8,Matches!$A:$A,"<"&R8) -> 0 | P8: =COUNTIFs(Matches!$C:$C,E8,Matches!$A:$A,">"&Q8,Matches!$A:$A,"<"&R8) -> 0 | Q8: =VLOOKUP($C$2,Quotas!$A$7:$E$14,2,FALSE) -> 46171.708 | R8: =VLOOKUP($C$2,Quotas!$A$7:$E$14,3,FALSE) -> 46178.708
A9: {=XLOOKUP($E9,'Player Database'!$B$2:$B252,'Player Database'!$C$2:$C252)} -> #N/A | B9: {=XLOOKUP($E9,'Player Database'!$B$2:$B252,'Player Database'!$E$2:$E252)} -> #N/A | C9: {=XLOOKUP($E9,'Player Database'!$B$2:$B252,'Player Database'!$F$2:$F252)} -> #N/A | D9: =IFERROR(__xludf.DUMMYFUNCTION("""COMPUTED_VALUE"""),1.0) -> 1 | F9: {=XLOOKUP($E9,'Player Database'!$B$2:$B252,'Player Database'!$K$2:$K252)} -> #N/A | G9: {=XLOOKUP($E9,'Player Database'!$B$2:$B252,'Player Database'!$AE$2:$AE252)} -> #N/A | H9: {=XLOOKUP($E9,'Player Database'!$B$2:$B252,'Player Database'!$H$2:$H252)} -> #N/A | I9: {=XLOOKUP($E9,'Player Database'!$B$2:$B252,'Player Database'!$O$2:$O252)} -> #N/A | J9: {=XLOOKUP($E9,'Player Database'!$B$2:$B252,'Player Database'!$P$2:$P252)} -> #N/A | K9: {=XLOOKUP($E9,'Player Database'!$B$2:$B252,'Player Database'!$U$2:$U252)} -> #N/A | L9: {=XLOOKUP($E9,'Player Database'!$B$2:$B252,'Player Database'!$W$2:$W252)} -> #N/A | M9: =CONCATENATE(O9," - ",P9) -> 0 - 0 | N9: {=IF(XLOOKUP($E9,'Player Database'!$B$2:$B252,'Player Database'!$AA$2:$AA252)="",XLOOKUP($E9,'Player Database'!$B$2:$B252,'Player Database'!$G$2:$G252),XLOOKUP($E9,'Player Database'!$B$2:$B252,'Player Database'!$AA$2:$AA252))} -> #N/A | O9: =COUNTIFs(Matches!$B:$B,E9,Matches!$A:$A,">"&Q9,Matches!$A:$A,"<"&R9) -> 0 | P9: =COUNTIFs(Matches!$C:$C,E9,Matches!$A:$A,">"&Q9,Matches!$A:$A,"<"&R9) -> 0 | Q9: =VLOOKUP($C$2,Quotas!$A$7:$E$14,2,FALSE) -> 46171.708 | R9: =VLOOKUP($C$2,Quotas!$A$7:$E$14,3,FALSE) -> 46178.708
A10: {=XLOOKUP($E10,'Player Database'!$B$2:$B252,'Player Database'!$C$2:$C252)} -> #N/A | B10: {=XLOOKUP($E10,'Player Database'!$B$2:$B252,'Player Database'!$E$2:$E252)} -> #N/A | C10: {=XLOOKUP($E10,'Player Database'!$B$2:$B252,'Player Database'!$F$2:$F252)} -> #N/A | D10: =IFERROR(__xludf.DUMMYFUNCTION("""COMPUTED_VALUE"""),1.0) -> 1 | F10: {=XLOOKUP($E10,'Player Database'!$B$2:$B252,'Player Database'!$K$2:$K252)} -> #N/A | G10: {=XLOOKUP($E10,'Player Database'!$B$2:$B252,'Player Database'!$AE$2:$AE252)} -> #N/A | H10: {=XLOOKUP($E10,'Player Database'!$B$2:$B252,'Player Database'!$H$2:$H252)} -> #N/A | I10: {=XLOOKUP($E10,'Player Database'!$B$2:$B252,'Player Database'!$O$2:$O252)} -> #N/A | J10: {=XLOOKUP($E10,'Player Database'!$B$2:$B252,'Player Database'!$P$2:$P252)} -> #N/A | K10: {=XLOOKUP($E10,'Player Database'!$B$2:$B252,'Player Database'!$U$2:$U252)} -> #N/A | L10: {=XLOOKUP($E10,'Player Database'!$B$2:$B252,'Player Database'!$W$2:$W252)} -> #N/A | M10: =CONCATENATE(O10," - ",P10) -> 0 - 0 | N10: {=IF(XLOOKUP($E10,'Player Database'!$B$2:$B252,'Player Database'!$AA$2:$AA252)="",XLOOKUP($E10,'Player Database'!$B$2:$B252,'Player Database'!$G$2:$G252),XLOOKUP($E10,'Player Database'!$B$2:$B252,'Player Database'!$AA$2:$AA252))} -> #N/A | O10: =COUNTIFs(Matches!$B:$B,E10,Matches!$A:$A,">"&Q10,Matches!$A:$A,"<"&R10) -> 0 | P10: =COUNTIFs(Matches!$C:$C,E10,Matches!$A:$A,">"&Q10,Matches!$A:$A,"<"&R10) -> 0 | Q10: =VLOOKUP($C$2,Quotas!$A$7:$E$14,2,FALSE) -> 46171.708 | R10: =VLOOKUP($C$2,Quotas!$A$7:$E$14,3,FALSE) -> 46178.708
A11: {=XLOOKUP($E11,'Player Database'!$B$2:$B252,'Player Database'!$C$2:$C252)} -> #N/A | B11: {=XLOOKUP($E11,'Player Database'!$B$2:$B252,'Player Database'!$E$2:$E252)} -> #N/A | C11: {=XLOOKUP($E11,'Player Database'!$B$2:$B252,'Player Database'!$F$2:$F252)} -> #N/A | D11: =IFERROR(__xludf.DUMMYFUNCTION("""COMPUTED_VALUE"""),1.0) -> 1 | F11: {=XLOOKUP($E11,'Player Database'!$B$2:$B252,'Player Database'!$K$2:$K252)} -> #N/A | G11: {=XLOOKUP($E11,'Player Database'!$B$2:$B252,'Player Database'!$AE$2:$AE252)} -> #N/A | H11: {=XLOOKUP($E11,'Player Database'!$B$2:$B252,'Player Database'!$H$2:$H252)} -> #N/A | I11: {=XLOOKUP($E11,'Player Database'!$B$2:$B252,'Player Database'!$O$2:$O252)} -> #N/A | J11: {=XLOOKUP($E11,'Player Database'!$B$2:$B252,'Player Database'!$P$2:$P252)} -> #N/A | K11: {=XLOOKUP($E11,'Player Database'!$B$2:$B252,'Player Database'!$U$2:$U252)} -> #N/A | L11: {=XLOOKUP($E11,'Player Database'!$B$2:$B252,'Player Database'!$W$2:$W252)} -> #N/A | M11: =CONCATENATE(O11," - ",P11) -> 0 - 0 | N11: {=IF(XLOOKUP($E11,'Player Database'!$B$2:$B252,'Player Database'!$AA$2:$AA252)="",XLOOKUP($E11,'Player Database'!$B$2:$B252,'Player Database'!$G$2:$G252),XLOOKUP($E11,'Player Database'!$B$2:$B252,'Player Database'!$AA$2:$AA252))} -> #N/A | O11: =COUNTIFs(Matches!$B:$B,E11,Matches!$A:$A,">"&Q11,Matches!$A:$A,"<"&R11) -> 0 | P11: =COUNTIFs(Matches!$C:$C,E11,Matches!$A:$A,">"&Q11,Matches!$A:$A,"<"&R11) -> 0 | Q11: =VLOOKUP($C$2,Quotas!$A$7:$E$14,2,FALSE) -> 46171.708 | R11: =VLOOKUP($C$2,Quotas!$A$7:$E$14,3,FALSE) -> 46178.708
A12: {=XLOOKUP($E12,'Player Database'!$B$2:$B252,'Player Database'!$C$2:$C252)} -> #N/A | B12: {=XLOOKUP($E12,'Player Database'!$B$2:$B252,'Player Database'!$E$2:$E252)} -> #N/A | C12: {=XLOOKUP($E12,'Player Database'!$B$2:$B252,'Player Database'!$F$2:$F252)} -> #N/A | D12: =IFERROR(__xludf.DUMMYFUNCTION("""COMPUTED_VALUE"""),1.0) -> 1 | F12: {=XLOOKUP($E12,'Player Database'!$B$2:$B252,'Player Database'!$K$2:$K252)} -> #N/A | G12: {=XLOOKUP($E12,'Player Database'!$B$2:$B252,'Player Database'!$AE$2:$AE252)} -> #N/A | H12: {=XLOOKUP($E12,'Player Database'!$B$2:$B252,'Player Database'!$H$2:$H252)} -> #N/A | I12: {=XLOOKUP($E12,'Player Database'!$B$2:$B252,'Player Database'!$O$2:$O252)} -> #N/A | J12: {=XLOOKUP($E12,'Player Database'!$B$2:$B252,'Player Database'!$P$2:$P252)} -> #N/A | K12: {=XLOOKUP($E12,'Player Database'!$B$2:$B252,'Player Database'!$U$2:$U252)} -> #N/A | L12: {=XLOOKUP($E12,'Player Database'!$B$2:$B252,'Player Database'!$W$2:$W252)} -> #N/A | M12: =CONCATENATE(O12," - ",P12) -> 0 - 0 | N12: {=IF(XLOOKUP($E12,'Player Database'!$B$2:$B252,'Player Database'!$AA$2:$AA252)="",XLOOKUP($E12,'Player Database'!$B$2:$B252,'Player Database'!$G$2:$G252),XLOOKUP($E12,'Player Database'!$B$2:$B252,'Player Database'!$AA$2:$AA252))} -> #N/A | O12: =COUNTIFs(Matches!$B:$B,E12,Matches!$A:$A,">"&Q12,Matches!$A:$A,"<"&R12) -> 0 | P12: =COUNTIFs(Matches!$C:$C,E12,Matches!$A:$A,">"&Q12,Matches!$A:$A,"<"&R12) -> 0 | Q12: =VLOOKUP($C$2,Quotas!$A$7:$E$14,2,FALSE) -> 46171.708 | R12: =VLOOKUP($C$2,Quotas!$A$7:$E$14,3,FALSE) -> 46178.708
A13: {=XLOOKUP($E13,'Player Database'!$B$2:$B252,'Player Database'!$C$2:$C252)} -> #N/A | B13: {=XLOOKUP($E13,'Player Database'!$B$2:$B252,'Player Database'!$E$2:$E252)} -> #N/A | C13: {=XLOOKUP($E13,'Player Database'!$B$2:$B252,'Player Database'!$F$2:$F252)} -> #N/A | D13: =IFERROR(__xludf.DUMMYFUNCTION("""COMPUTED_VALUE"""),1.0) -> 1 | F13: {=XLOOKUP($E13,'Player Database'!$B$2:$B252,'Player Database'!$K$2:$K252)} -> #N/A | G13: {=XLOOKUP($E13,'Player Database'!$B$2:$B252,'Player Database'!$AE$2:$AE252)} -> #N/A | H13: {=XLOOKUP($E13,'Player Database'!$B$2:$B252,'Player Database'!$H$2:$H252)} -> #N/A | I13: {=XLOOKUP($E13,'Player Database'!$B$2:$B252,'Player Database'!$O$2:$O252)} -> #N/A | J13: {=XLOOKUP($E13,'Player Database'!$B$2:$B252,'Player Database'!$P$2:$P252)} -> #N/A | K13: {=XLOOKUP($E13,'Player Database'!$B$2:$B252,'Player Database'!$U$2:$U252)} -> #N/A | L13: {=XLOOKUP($E13,'Player Database'!$B$2:$B252,'Player Database'!$W$2:$W252)} -> #N/A | M13: =CONCATENATE(O13," - ",P13) -> 0 - 0 | N13: {=IF(XLOOKUP($E13,'Player Database'!$B$2:$B252,'Player Database'!$AA$2:$AA252)="",XLOOKUP($E13,'Player Database'!$B$2:$B252,'Player Database'!$G$2:$G252),XLOOKUP($E13,'Player Database'!$B$2:$B252,'Player Database'!$AA$2:$AA252))} -> #N/A | O13: =COUNTIFs(Matches!$B:$B,E13,Matches!$A:$A,">"&Q13,Matches!$A:$A,"<"&R13) -> 0 | P13: =COUNTIFs(Matches!$C:$C,E13,Matches!$A:$A,">"&Q13,Matches!$A:$A,"<"&R13) -> 0 | Q13: =VLOOKUP($C$2,Quotas!$A$7:$E$14,2,FALSE) -> 46171.708 | R13: =VLOOKUP($C$2,Quotas!$A$7:$E$14,3,FALSE) -> 46178.708
A14: {=XLOOKUP($E14,'Player Database'!$B$2:$B252,'Player Database'!$C$2:$C252)} -> #N/A | B14: {=XLOOKUP($E14,'Player Database'!$B$2:$B252,'Player Database'!$E$2:$E252)} -> #N/A | C14: {=XLOOKUP($E14,'Player Database'!$B$2:$B252,'Player Database'!$F$2:$F252)} -> #N/A | D14: =IFERROR(__xludf.DUMMYFUNCTION("""COMPUTED_VALUE"""),1.0) -> 1 | F14: {=XLOOKUP($E14,'Player Database'!$B$2:$B252,'Player Database'!$K$2:$K252)} -> #N/A | G14: {=XLOOKUP($E14,'Player Database'!$B$2:$B252,'Player Database'!$AE$2:$AE252)} -> #N/A | H14: {=XLOOKUP($E14,'Player Database'!$B$2:$B252,'Player Database'!$H$2:$H252)} -> #N/A | I14: {=XLOOKUP($E14,'Player Database'!$B$2:$B252,'Player Database'!$O$2:$O252)} -> #N/A | J14: {=XLOOKUP($E14,'Player Database'!$B$2:$B252,'Player Database'!$P$2:$P252)} -> #N/A | K14: {=XLOOKUP($E14,'Player Database'!$B$2:$B252,'Player Database'!$U$2:$U252)} -> #N/A | L14: {=XLOOKUP($E14,'Player Database'!$B$2:$B252,'Player Database'!$W$2:$W252)} -> #N/A | M14: =CONCATENATE(O14," - ",P14) -> 0 - 0 | N14: {=IF(XLOOKUP($E14,'Player Database'!$B$2:$B252,'Player Database'!$AA$2:$AA252)="",XLOOKUP($E14,'Player Database'!$B$2:$B252,'Player Database'!$G$2:$G252),XLOOKUP($E14,'Player Database'!$B$2:$B252,'Player Database'!$AA$2:$AA252))} -> #N/A | O14: =COUNTIFs(Matches!$B:$B,E14,Matches!$A:$A,">"&Q14,Matches!$A:$A,"<"&R14) -> 0 | P14: =COUNTIFs(Matches!$C:$C,E14,Matches!$A:$A,">"&Q14,Matches!$A:$A,"<"&R14) -> 0 | Q14: =VLOOKUP($C$2,Quotas!$A$7:$E$14,2,FALSE) -> 46171.708 | R14: =VLOOKUP($C$2,Quotas!$A$7:$E$14,3,FALSE) -> 46178.708
A15: {=XLOOKUP($E15,'Player Database'!$B$2:$B252,'Player Database'!$C$2:$C252)} -> #N/A | B15: {=XLOOKUP($E15,'Player Database'!$B$2:$B252,'Player Database'!$E$2:$E252)} -> #N/A | C15: {=XLOOKUP($E15,'Player Database'!$B$2:$B252,'Player Database'!$F$2:$F252)} -> #N/A | D15: =IFERROR(__xludf.DUMMYFUNCTION("""COMPUTED_VALUE"""),1.0) -> 1 | F15: {=XLOOKUP($E15,'Player Database'!$B$2:$B252,'Player Database'!$K$2:$K252)} -> #N/A | G15: {=XLOOKUP($E15,'Player Database'!$B$2:$B252,'Player Database'!$AE$2:$AE252)} -> #N/A | H15: {=XLOOKUP($E15,'Player Database'!$B$2:$B252,'Player Database'!$H$2:$H252)} -> #N/A | I15: {=XLOOKUP($E15,'Player Database'!$B$2:$B252,'Player Database'!$O$2:$O252)} -> #N/A | J15: {=XLOOKUP($E15,'Player Database'!$B$2:$B252,'Player Database'!$P$2:$P252)} -> #N/A | K15: {=XLOOKUP($E15,'Player Database'!$B$2:$B252,'Player Database'!$U$2:$U252)} -> #N/A | L15: {=XLOOKUP($E15,'Player Database'!$B$2:$B252,'Player Database'!$W$2:$W252)} -> #N/A | M15: =CONCATENATE(O15," - ",P15) -> 0 - 0 | N15: {=IF(XLOOKUP($E15,'Player Database'!$B$2:$B252,'Player Database'!$AA$2:$AA252)="",XLOOKUP($E15,'Player Database'!$B$2:$B252,'Player Database'!$G$2:$G252),XLOOKUP($E15,'Player Database'!$B$2:$B252,'Player Database'!$AA$2:$AA252))} -> #N/A | O15: =COUNTIFs(Matches!$B:$B,E15,Matches!$A:$A,">"&Q15,Matches!$A:$A,"<"&R15) -> 0 | P15: =COUNTIFs(Matches!$C:$C,E15,Matches!$A:$A,">"&Q15,Matches!$A:$A,"<"&R15) -> 0 | Q15: =VLOOKUP($C$2,Quotas!$A$7:$E$14,2,FALSE) -> 46171.708 | R15: =VLOOKUP($C$2,Quotas!$A$7:$E$14,3,FALSE) -> 46178.708
A16: {=XLOOKUP($E16,'Player Database'!$B$2:$B252,'Player Database'!$C$2:$C252)} -> #N/A | B16: {=XLOOKUP($E16,'Player Database'!$B$2:$B252,'Player Database'!$E$2:$E252)} -> #N/A | C16: {=XLOOKUP($E16,'Player Database'!$B$2:$B252,'Player Database'!$F$2:$F252)} -> #N/A | D16: =IFERROR(__xludf.DUMMYFUNCTION("""COMPUTED_VALUE"""),1.0) -> 1 | F16: {=XLOOKUP($E16,'Player Database'!$B$2:$B252,'Player Database'!$K$2:$K252)} -> #N/A | G16: {=XLOOKUP($E16,'Player Database'!$B$2:$B252,'Player Database'!$AE$2:$AE252)} -> #N/A | H16: {=XLOOKUP($E16,'Player Database'!$B$2:$B252,'Player Database'!$H$2:$H252)} -> #N/A | I16: {=XLOOKUP($E16,'Player Database'!$B$2:$B252,'Player Database'!$O$2:$O252)} -> #N/A | J16: {=XLOOKUP($E16,'Player Database'!$B$2:$B252,'Player Database'!$P$2:$P252)} -> #N/A | K16: {=XLOOKUP($E16,'Player Database'!$B$2:$B252,'Player Database'!$U$2:$U252)} -> #N/A | L16: {=XLOOKUP($E16,'Player Database'!$B$2:$B252,'Player Database'!$W$2:$W252)} -> #N/A | M16: =CONCATENATE(O16," - ",P16) -> 0 - 0 | N16: {=IF(XLOOKUP($E16,'Player Database'!$B$2:$B252,'Player Database'!$AA$2:$AA252)="",XLOOKUP($E16,'Player Database'!$B$2:$B252,'Player Database'!$G$2:$G252),XLOOKUP($E16,'Player Database'!$B$2:$B252,'Player Database'!$AA$2:$AA252))} -> #N/A | O16: =COUNTIFs(Matches!$B:$B,E16,Matches!$A:$A,">"&Q16,Matches!$A:$A,"<"&R16) -> 0 | P16: =COUNTIFs(Matches!$C:$C,E16,Matches!$A:$A,">"&Q16,Matches!$A:$A,"<"&R16) -> 0 | Q16: =VLOOKUP($C$2,Quotas!$A$7:$E$14,2,FALSE) -> 46171.708 | R16: =VLOOKUP($C$2,Quotas!$A$7:$E$14,3,FALSE) -> 46178.708
A17: {=XLOOKUP($E17,'Player Database'!$B$2:$B252,'Player Database'!$C$2:$C252)} -> #N/A | B17: {=XLOOKUP($E17,'Player Database'!$B$2:$B252,'Player Database'!$E$2:$E252)} -> #N/A | C17: {=XLOOKUP($E17,'Player Database'!$B$2:$B252,'Player Database'!$F$2:$F252)} -> #N/A | D17: =IFERROR(__xludf.DUMMYFUNCTION("""COMPUTED_VALUE"""),1.0) -> 1 | F17: {=XLOOKUP($E17,'Player Database'!$B$2:$B252,'Player Database'!$K$2:$K252)} -> #N/A | G17: {=XLOOKUP($E17,'Player Database'!$B$2:$B252,'Player Database'!$AE$2:$AE252)} -> #N/A | H17: {=XLOOKUP($E17,'Player Database'!$B$2:$B252,'Player Database'!$H$2:$H252)} -> #N/A | I17: {=XLOOKUP($E17,'Player Database'!$B$2:$B252,'Player Database'!$O$2:$O252)} -> #N/A | J17: {=XLOOKUP($E17,'Player Database'!$B$2:$B252,'Player Database'!$P$2:$P252)} -> #N/A | K17: {=XLOOKUP($E17,'Player Database'!$B$2:$B252,'Player Database'!$U$2:$U252)} -> #N/A | L17: {=XLOOKUP($E17,'Player Database'!$B$2:$B252,'Player Database'!$W$2:$W252)} -> #N/A | M17: =CONCATENATE(O17," - ",P17) -> 0 - 0 | N17: {=IF(XLOOKUP($E17,'Player Database'!$B$2:$B252,'Player Database'!$AA$2:$AA252)="",XLOOKUP($E17,'Player Database'!$B$2:$B252,'Player Database'!$G$2:$G252),XLOOKUP($E17,'Player Database'!$B$2:$B252,'Player Database'!$AA$2:$AA252))} -> #N/A | O17: =COUNTIFs(Matches!$B:$B,E17,Matches!$A:$A,">"&Q17,Matches!$A:$A,"<"&R17) -> 0 | P17: =COUNTIFs(Matches!$C:$C,E17,Matches!$A:$A,">"&Q17,Matches!$A:$A,"<"&R17) -> 0 | Q17: =VLOOKUP($C$2,Quotas!$A$7:$E$14,2,FALSE) -> 46171.708 | R17: =VLOOKUP($C$2,Quotas!$A$7:$E$14,3,FALSE) -> 46178.708
A18: {=XLOOKUP($E18,'Player Database'!$B$2:$B252,'Player Database'!$C$2:$C252)} -> #N/A | B18: {=XLOOKUP($E18,'Player Database'!$B$2:$B252,'Player Database'!$E$2:$E252)} -> #N/A | C18: {=XLOOKUP($E18,'Player Database'!$B$2:$B252,'Player Database'!$F$2:$F252)} -> #N/A | D18: =IFERROR(__xludf.DUMMYFUNCTION("""COMPUTED_VALUE"""),1.0) -> 1 | F18: {=XLOOKUP($E18,'Player Database'!$B$2:$B252,'Player Database'!$K$2:$K252)} -> #N/A | G18: {=XLOOKUP($E18,'Player Database'!$B$2:$B252,'Player Database'!$AE$2:$AE252)} -> #N/A | H18: {=XLOOKUP($E18,'Player Database'!$B$2:$B252,'Player Database'!$H$2:$H252)} -> #N/A | I18: {=XLOOKUP($E18,'Player Database'!$B$2:$B252,'Player Database'!$O$2:$O252)} -> #N/A | J18: {=XLOOKUP($E18,'Player Database'!$B$2:$B252,'Player Database'!$P$2:$P252)} -> #N/A | K18: {=XLOOKUP($E18,'Player Database'!$B$2:$B252,'Player Database'!$U$2:$U252)} -> #N/A | L18: {=XLOOKUP($E18,'Player Database'!$B$2:$B252,'Player Database'!$W$2:$W252)} -> #N/A | M18: =CONCATENATE(O18," - ",P18) -> 0 - 0 | N18: {=IF(XLOOKUP($E18,'Player Database'!$B$2:$B252,'Player Database'!$AA$2:$AA252)="",XLOOKUP($E18,'Player Database'!$B$2:$B252,'Player Database'!$G$2:$G252),XLOOKUP($E18,'Player Database'!$B$2:$B252,'Player Database'!$AA$2:$AA252))} -> #N/A | O18: =COUNTIFs(Matches!$B:$B,E18,Matches!$A:$A,">"&Q18,Matches!$A:$A,"<"&R18) -> 0 | P18: =COUNTIFs(Matches!$C:$C,E18,Matches!$A:$A,">"&Q18,Matches!$A:$A,"<"&R18) -> 0 | Q18: =VLOOKUP($C$2,Quotas!$A$7:$E$14,2,FALSE) -> 46171.708 | R18: =VLOOKUP($C$2,Quotas!$A$7:$E$14,3,FALSE) -> 46178.708
A19: {=XLOOKUP($E19,'Player Database'!$B$2:$B252,'Player Database'!$C$2:$C252)} -> #N/A | B19: {=XLOOKUP($E19,'Player Database'!$B$2:$B252,'Player Database'!$E$2:$E252)} -> #N/A | C19: {=XLOOKUP($E19,'Player Database'!$B$2:$B252,'Player Database'!$F$2:$F252)} -> #N/A | D19: =IFERROR(__xludf.DUMMYFUNCTION("""COMPUTED_VALUE"""),1.0) -> 1 | F19: {=XLOOKUP($E19,'Player Database'!$B$2:$B252,'Player Database'!$K$2:$K252)} -> #N/A | G19: {=XLOOKUP($E19,'Player Database'!$B$2:$B252,'Player Database'!$AE$2:$AE252)} -> #N/A | H19: {=XLOOKUP($E19,'Player Database'!$B$2:$B252,'Player Database'!$H$2:$H252)} -> #N/A | I19: {=XLOOKUP($E19,'Player Database'!$B$2:$B252,'Player Database'!$O$2:$O252)} -> #N/A | J19: {=XLOOKUP($E19,'Player Database'!$B$2:$B252,'Player Database'!$P$2:$P252)} -> #N/A | K19: {=XLOOKUP($E19,'Player Database'!$B$2:$B252,'Player Database'!$U$2:$U252)} -> #N/A | L19: {=XLOOKUP($E19,'Player Database'!$B$2:$B252,'Player Database'!$W$2:$W252)} -> #N/A | M19: =CONCATENATE(O19," - ",P19) -> 0 - 0 | N19: {=IF(XLOOKUP($E19,'Player Database'!$B$2:$B252,'Player Database'!$AA$2:$AA252)="",XLOOKUP($E19,'Player Database'!$B$2:$B252,'Player Database'!$G$2:$G252),XLOOKUP($E19,'Player Database'!$B$2:$B252,'Player Database'!$AA$2:$AA252))} -> #N/A | O19: =COUNTIFs(Matches!$B:$B,E19,Matches!$A:$A,">"&Q19,Matches!$A:$A,"<"&R19) -> 0 | P19: =COUNTIFs(Matches!$C:$C,E19,Matches!$A:$A,">"&Q19,Matches!$A:$A,"<"&R19) -> 0 | Q19: =VLOOKUP($C$2,Quotas!$A$7:$E$14,2,FALSE) -> 46171.708 | R19: =VLOOKUP($C$2,Quotas!$A$7:$E$14,3,FALSE) -> 46178.708
A20: {=XLOOKUP($E20,'Player Database'!$B$2:$B252,'Player Database'!$C$2:$C252)} -> #N/A | B20: {=XLOOKUP($E20,'Player Database'!$B$2:$B252,'Player Database'!$E$2:$E252)} -> #N/A | C20: {=XLOOKUP($E20,'Player Database'!$B$2:$B252,'Player Database'!$F$2:$F252)} -> #N/A | D20: =IFERROR(__xludf.DUMMYFUNCTION("""COMPUTED_VALUE"""),1.0) -> 1 | F20: {=XLOOKUP($E20,'Player Database'!$B$2:$B252,'Player Database'!$K$2:$K252)} -> #N/A | G20: {=XLOOKUP($E20,'Player Database'!$B$2:$B252,'Player Database'!$AE$2:$AE252)} -> #N/A | H20: {=XLOOKUP($E20,'Player Database'!$B$2:$B252,'Player Database'!$H$2:$H252)} -> #N/A | I20: {=XLOOKUP($E20,'Player Database'!$B$2:$B252,'Player Database'!$O$2:$O252)} -> #N/A | J20: {=XLOOKUP($E20,'Player Database'!$B$2:$B252,'Player Database'!$P$2:$P252)} -> #N/A | K20: {=XLOOKUP($E20,'Player Database'!$B$2:$B252,'Player Database'!$U$2:$U252)} -> #N/A | L20: {=XLOOKUP($E20,'Player Database'!$B$2:$B252,'Player Database'!$W$2:$W252)} -> #N/A | M20: =CONCATENATE(O20," - ",P20) -> 0 - 0 | N20: {=IF(XLOOKUP($E20,'Player Database'!$B$2:$B252,'Player Database'!$AA$2:$AA252)="",XLOOKUP($E20,'Player Database'!$B$2:$B252,'Player Database'!$G$2:$G252),XLOOKUP($E20,'Player Database'!$B$2:$B252,'Player Database'!$AA$2:$AA252))} -> #N/A | O20: =COUNTIFs(Matches!$B:$B,E20,Matches!$A:$A,">"&Q20,Matches!$A:$A,"<"&R20) -> 0 | P20: =COUNTIFs(Matches!$C:$C,E20,Matches!$A:$A,">"&Q20,Matches!$A:$A,"<"&R20) -> 0 | Q20: =VLOOKUP($C$2,Quotas!$A$7:$E$14,2,FALSE) -> 46171.708 | R20: =VLOOKUP($C$2,Quotas!$A$7:$E$14,3,FALSE) -> 46178.708
A21: {=XLOOKUP($E21,'Player Database'!$B$2:$B252,'Player Database'!$C$2:$C252)} -> #N/A | B21: {=XLOOKUP($E21,'Player Database'!$B$2:$B252,'Player Database'!$E$2:$E252)} -> #N/A | C21: {=XLOOKUP($E21,'Player Database'!$B$2:$B252,'Player Database'!$F$2:$F252)} -> #N/A | D21: =IFERROR(__xludf.DUMMYFUNCTION("""COMPUTED_VALUE"""),1.0) -> 1 | F21: {=XLOOKUP($E21,'Player Database'!$B$2:$B252,'Player Database'!$K$2:$K252)} -> #N/A | G21: {=XLOOKUP($E21,'Player Database'!$B$2:$B252,'Player Database'!$AE$2:$AE252)} -> #N/A | H21: {=XLOOKUP($E21,'Player Database'!$B$2:$B252,'Player Database'!$H$2:$H252)} -> #N/A | I21: {=XLOOKUP($E21,'Player Database'!$B$2:$B252,'Player Database'!$O$2:$O252)} -> #N/A | J21: {=XLOOKUP($E21,'Player Database'!$B$2:$B252,'Player Database'!$P$2:$P252)} -> #N/A | K21: {=XLOOKUP($E21,'Player Database'!$B$2:$B252,'Player Database'!$U$2:$U252)} -> #N/A | L21: {=XLOOKUP($E21,'Player Database'!$B$2:$B252,'Player Database'!$W$2:$W252)} -> #N/A | M21: =CONCATENATE(O21," - ",P21) -> 0 - 0 | N21: {=IF(XLOOKUP($E21,'Player Database'!$B$2:$B252,'Player Database'!$AA$2:$AA252)="",XLOOKUP($E21,'Player Database'!$B$2:$B252,'Player Database'!$G$2:$G252),XLOOKUP($E21,'Player Database'!$B$2:$B252,'Player Database'!$AA$2:$AA252))} -> #N/A | O21: =COUNTIFs(Matches!$B:$B,E21,Matches!$A:$A,">"&Q21,Matches!$A:$A,"<"&R21) -> 0 | P21: =COUNTIFs(Matches!$C:$C,E21,Matches!$A:$A,">"&Q21,Matches!$A:$A,"<"&R21) -> 0 | Q21: =VLOOKUP($C$2,Quotas!$A$7:$E$14,2,FALSE) -> 46171.708 | R21: =VLOOKUP($C$2,Quotas!$A$7:$E$14,3,FALSE) -> 46178.708
A22: {=XLOOKUP($E22,'Player Database'!$B$2:$B252,'Player Database'!$C$2:$C252)} -> #N/A | B22: {=XLOOKUP($E22,'Player Database'!$B$2:$B252,'Player Database'!$E$2:$E252)} -> #N/A | C22: {=XLOOKUP($E22,'Player Database'!$B$2:$B252,'Player Database'!$F$2:$F252)} -> #N/A | D22: =IFERROR(__xludf.DUMMYFUNCTION("""COMPUTED_VALUE"""),1.0) -> 1 | F22: {=XLOOKUP($E22,'Player Database'!$B$2:$B252,'Player Database'!$K$2:$K252)} -> #N/A | G22: {=XLOOKUP($E22,'Player Database'!$B$2:$B252,'Player Database'!$AE$2:$AE252)} -> #N/A | H22: {=XLOOKUP($E22,'Player Database'!$B$2:$B252,'Player Database'!$H$2:$H252)} -> #N/A | I22: {=XLOOKUP($E22,'Player Database'!$B$2:$B252,'Player Database'!$O$2:$O252)} -> #N/A | J22: {=XLOOKUP($E22,'Player Database'!$B$2:$B252,'Player Database'!$P$2:$P252)} -> #N/A | K22: {=XLOOKUP($E22,'Player Database'!$B$2:$B252,'Player Database'!$U$2:$U252)} -> #N/A | L22: {=XLOOKUP($E22,'Player Database'!$B$2:$B252,'Player Database'!$W$2:$W252)} -> #N/A | M22: =CONCATENATE(O22," - ",P22) -> 0 - 0 | N22: {=IF(XLOOKUP($E22,'Player Database'!$B$2:$B252,'Player Database'!$AA$2:$AA252)="",XLOOKUP($E22,'Player Database'!$B$2:$B252,'Player Database'!$G$2:$G252),XLOOKUP($E22,'Player Database'!$B$2:$B252,'Player Database'!$AA$2:$AA252))} -> #N/A | O22: =COUNTIFs(Matches!$B:$B,E22,Matches!$A:$A,">"&Q22,Matches!$A:$A,"<"&R22) -> 0 | P22: =COUNTIFs(Matches!$C:$C,E22,Matches!$A:$A,">"&Q22,Matches!$A:$A,"<"&R22) -> 0 | Q22: =VLOOKUP($C$2,Quotas!$A$7:$E$14,2,FALSE) -> 46171.708 | R22: =VLOOKUP($C$2,Quotas!$A$7:$E$14,3,FALSE) -> 46178.708
A23: {=XLOOKUP($E23,'Player Database'!$B$2:$B252,'Player Database'!$C$2:$C252)} -> #N/A | B23: {=XLOOKUP($E23,'Player Database'!$B$2:$B252,'Player Database'!$E$2:$E252)} -> #N/A | C23: {=XLOOKUP($E23,'Player Database'!$B$2:$B252,'Player Database'!$F$2:$F252)} -> #N/A | D23: =IFERROR(__xludf.DUMMYFUNCTION("""COMPUTED_VALUE"""),1.0) -> 1 | F23: {=XLOOKUP($E23,'Player Database'!$B$2:$B252,'Player Database'!$K$2:$K252)} -> #N/A | G23: {=XLOOKUP($E23,'Player Database'!$B$2:$B252,'Player Database'!$AE$2:$AE252)} -> #N/A | H23: {=XLOOKUP($E23,'Player Database'!$B$2:$B252,'Player Database'!$H$2:$H252)} -> #N/A | I23: {=XLOOKUP($E23,'Player Database'!$B$2:$B252,'Player Database'!$O$2:$O252)} -> #N/A | J23: {=XLOOKUP($E23,'Player Database'!$B$2:$B252,'Player Database'!$P$2:$P252)} -> #N/A | K23: {=XLOOKUP($E23,'Player Database'!$B$2:$B252,'Player Database'!$U$2:$U252)} -> #N/A | L23: {=XLOOKUP($E23,'Player Database'!$B$2:$B252,'Player Database'!$W$2:$W252)} -> #N/A | M23: =CONCATENATE(O23," - ",P23) -> 0 - 0 | N23: {=IF(XLOOKUP($E23,'Player Database'!$B$2:$B252,'Player Database'!$AA$2:$AA252)="",XLOOKUP($E23,'Player Database'!$B$2:$B252,'Player Database'!$G$2:$G252),XLOOKUP($E23,'Player Database'!$B$2:$B252,'Player Database'!$AA$2:$AA252))} -> #N/A | O23: =COUNTIFs(Matches!$B:$B,E23,Matches!$A:$A,">"&Q23,Matches!$A:$A,"<"&R23) -> 0 | P23: =COUNTIFs(Matches!$C:$C,E23,Matches!$A:$A,">"&Q23,Matches!$A:$A,"<"&R23) -> 0 | Q23: =VLOOKUP($C$2,Quotas!$A$7:$E$14,2,FALSE) -> 46171.708 | R23: =VLOOKUP($C$2,Quotas!$A$7:$E$14,3,FALSE) -> 46178.708
A24: {=XLOOKUP($E24,'Player Database'!$B$2:$B252,'Player Database'!$C$2:$C252)} -> #N/A | B24: {=XLOOKUP($E24,'Player Database'!$B$2:$B252,'Player Database'!$E$2:$E252)} -> #N/A | C24: {=XLOOKUP($E24,'Player Database'!$B$2:$B252,'Player Database'!$F$2:$F252)} -> #N/A | D24: =IFERROR(__xludf.DUMMYFUNCTION("""COMPUTED_VALUE"""),1.0) -> 1 | F24: {=XLOOKUP($E24,'Player Database'!$B$2:$B252,'Player Database'!$K$2:$K252)} -> #N/A | G24: {=XLOOKUP($E24,'Player Database'!$B$2:$B252,'Player Database'!$AE$2:$AE252)} -> #N/A | H24: {=XLOOKUP($E24,'Player Database'!$B$2:$B252,'Player Database'!$H$2:$H252)} -> #N/A | I24: {=XLOOKUP($E24,'Player Database'!$B$2:$B252,'Player Database'!$O$2:$O252)} -> #N/A | J24: {=XLOOKUP($E24,'Player Database'!$B$2:$B252,'Player Database'!$P$2:$P252)} -> #N/A | K24: {=XLOOKUP($E24,'Player Database'!$B$2:$B252,'Player Database'!$U$2:$U252)} -> #N/A | L24: {=XLOOKUP($E24,'Player Database'!$B$2:$B252,'Player Database'!$W$2:$W252)} -> #N/A | M24: =CONCATENATE(O24," - ",P24) -> 0 - 0 | N24: {=IF(XLOOKUP($E24,'Player Database'!$B$2:$B252,'Player Database'!$AA$2:$AA252)="",XLOOKUP($E24,'Player Database'!$B$2:$B252,'Player Database'!$G$2:$G252),XLOOKUP($E24,'Player Database'!$B$2:$B252,'Player Database'!$AA$2:$AA252))} -> #N/A | O24: =COUNTIFs(Matches!$B:$B,E24,Matches!$A:$A,">"&Q24,Matches!$A:$A,"<"&R24) -> 0 | P24: =COUNTIFs(Matches!$C:$C,E24,Matches!$A:$A,">"&Q24,Matches!$A:$A,"<"&R24) -> 0 | Q24: =VLOOKUP($C$2,Quotas!$A$7:$E$14,2,FALSE) -> 46171.708 | R24: =VLOOKUP($C$2,Quotas!$A$7:$E$14,3,FALSE) -> 46178.708
A25: {=XLOOKUP($E25,'Player Database'!$B$2:$B252,'Player Database'!$C$2:$C252)} -> #N/A | B25: {=XLOOKUP($E25,'Player Database'!$B$2:$B252,'Player Database'!$E$2:$E252)} -> #N/A | C25: {=XLOOKUP($E25,'Player Database'!$B$2:$B252,'Player Database'!$F$2:$F252)} -> #N/A | D25: =IFERROR(__xludf.DUMMYFUNCTION("""COMPUTED_VALUE"""),1.0) -> 1 | F25: {=XLOOKUP($E25,'Player Database'!$B$2:$B252,'Player Database'!$K$2:$K252)} -> #N/A | G25: {=XLOOKUP($E25,'Player Database'!$B$2:$B252,'Player Database'!$AE$2:$AE252)} -> #N/A | H25: {=XLOOKUP($E25,'Player Database'!$B$2:$B252,'Player Database'!$H$2:$H252)} -> #N/A | I25: {=XLOOKUP($E25,'Player Database'!$B$2:$B252,'Player Database'!$O$2:$O252)} -> #N/A | J25: {=XLOOKUP($E25,'Player Database'!$B$2:$B252,'Player Database'!$P$2:$P252)} -> #N/A | K25: {=XLOOKUP($E25,'Player Database'!$B$2:$B252,'Player Database'!$U$2:$U252)} -> #N/A | L25: {=XLOOKUP($E25,'Player Database'!$B$2:$B252,'Player Database'!$W$2:$W252)} -> #N/A | M25: =CONCATENATE(O25," - ",P25) -> 0 - 0 | N25: {=IF(XLOOKUP($E25,'Player Database'!$B$2:$B252,'Player Database'!$AA$2:$AA252)="",XLOOKUP($E25,'Player Database'!$B$2:$B252,'Player Database'!$G$2:$G252),XLOOKUP($E25,'Player Database'!$B$2:$B252,'Player Database'!$AA$2:$AA252))} -> #N/A | O25: =COUNTIFs(Matches!$B:$B,E25,Matches!$A:$A,">"&Q25,Matches!$A:$A,"<"&R25) -> 0 | P25: =COUNTIFs(Matches!$C:$C,E25,Matches!$A:$A,">"&Q25,Matches!$A:$A,"<"&R25) -> 0 | Q25: =VLOOKUP($C$2,Quotas!$A$7:$E$14,2,FALSE) -> 46171.708 | R25: =VLOOKUP($C$2,Quotas!$A$7:$E$14,3,FALSE) -> 46178.708
A26: {=XLOOKUP($E26,'Player Database'!$B$2:$B252,'Player Database'!$C$2:$C252)} -> #N/A | B26: {=XLOOKUP($E26,'Player Database'!$B$2:$B252,'Player Database'!$E$2:$E252)} -> #N/A | C26: {=XLOOKUP($E26,'Player Database'!$B$2:$B252,'Player Database'!$F$2:$F252)} -> #N/A | D26: =IFERROR(__xludf.DUMMYFUNCTION("""COMPUTED_VALUE"""),1.0) -> 1 | F26: {=XLOOKUP($E26,'Player Database'!$B$2:$B252,'Player Database'!$K$2:$K252)} -> #N/A | G26: {=XLOOKUP($E26,'Player Database'!$B$2:$B252,'Player Database'!$AE$2:$AE252)} -> #N/A | H26: {=XLOOKUP($E26,'Player Database'!$B$2:$B252,'Player Database'!$H$2:$H252)} -> #N/A | I26: {=XLOOKUP($E26,'Player Database'!$B$2:$B252,'Player Database'!$O$2:$O252)} -> #N/A | J26: {=XLOOKUP($E26,'Player Database'!$B$2:$B252,'Player Database'!$P$2:$P252)} -> #N/A | K26: {=XLOOKUP($E26,'Player Database'!$B$2:$B252,'Player Database'!$U$2:$U252)} -> #N/A | L26: {=XLOOKUP($E26,'Player Database'!$B$2:$B252,'Player Database'!$W$2:$W252)} -> #N/A | M26: =CONCATENATE(O26," - ",P26) -> 0 - 0 | N26: {=IF(XLOOKUP($E26,'Player Database'!$B$2:$B252,'Player Database'!$AA$2:$AA252)="",XLOOKUP($E26,'Player Database'!$B$2:$B252,'Player Database'!$G$2:$G252),XLOOKUP($E26,'Player Database'!$B$2:$B252,'Player Database'!$AA$2:$AA252))} -> #N/A | O26: =COUNTIFs(Matches!$B:$B,E26,Matches!$A:$A,">"&Q26,Matches!$A:$A,"<"&R26) -> 0 | P26: =COUNTIFs(Matches!$C:$C,E26,Matches!$A:$A,">"&Q26,Matches!$A:$A,"<"&R26) -> 0 | Q26: =VLOOKUP($C$2,Quotas!$A$7:$E$14,2,FALSE) -> 46171.708 | R26: =VLOOKUP($C$2,Quotas!$A$7:$E$14,3,FALSE) -> 46178.708
A27: {=XLOOKUP($E27,'Player Database'!$B$2:$B252,'Player Database'!$C$2:$C252)} -> #N/A | B27: {=XLOOKUP($E27,'Player Database'!$B$2:$B252,'Player Database'!$E$2:$E252)} -> #N/A | C27: {=XLOOKUP($E27,'Player Database'!$B$2:$B252,'Player Database'!$F$2:$F252)} -> #N/A | D27: =IFERROR(__xludf.DUMMYFUNCTION("""COMPUTED_VALUE"""),1.0) -> 1 | F27: {=XLOOKUP($E27,'Player Database'!$B$2:$B252,'Player Database'!$K$2:$K252)} -> #N/A | G27: {=XLOOKUP($E27,'Player Database'!$B$2:$B252,'Player Database'!$AE$2:$AE252)} -> #N/A | H27: {=XLOOKUP($E27,'Player Database'!$B$2:$B252,'Player Database'!$H$2:$H252)} -> #N/A | I27: {=XLOOKUP($E27,'Player Database'!$B$2:$B252,'Player Database'!$O$2:$O252)} -> #N/A | J27: {=XLOOKUP($E27,'Player Database'!$B$2:$B252,'Player Database'!$P$2:$P252)} -> #N/A | K27: {=XLOOKUP($E27,'Player Database'!$B$2:$B252,'Player Database'!$U$2:$U252)} -> #N/A | L27: {=XLOOKUP($E27,'Player Database'!$B$2:$B252,'Player Database'!$W$2:$W252)} -> #N/A | M27: =CONCATENATE(O27," - ",P27) -> 0 - 0 | N27: {=IF(XLOOKUP($E27,'Player Database'!$B$2:$B252,'Player Database'!$AA$2:$AA252)="",XLOOKUP($E27,'Player Database'!$B$2:$B252,'Player Database'!$G$2:$G252),XLOOKUP($E27,'Player Database'!$B$2:$B252,'Player Database'!$AA$2:$AA252))} -> #N/A | O27: =COUNTIFs(Matches!$B:$B,E27,Matches!$A:$A,">"&Q27,Matches!$A:$A,"<"&R27) -> 0 | P27: =COUNTIFs(Matches!$C:$C,E27,Matches!$A:$A,">"&Q27,Matches!$A:$A,"<"&R27) -> 0 | Q27: =VLOOKUP($C$2,Quotas!$A$7:$E$14,2,FALSE) -> 46171.708 | R27: =VLOOKUP($C$2,Quotas!$A$7:$E$14,3,FALSE) -> 46178.708
A28: {=XLOOKUP($E28,'Player Database'!$B$2:$B252,'Player Database'!$C$2:$C252)} -> #N/A | B28: {=XLOOKUP($E28,'Player Database'!$B$2:$B252,'Player Database'!$E$2:$E252)} -> #N/A | C28: {=XLOOKUP($E28,'Player Database'!$B$2:$B252,'Player Database'!$F$2:$F252)} -> #N/A | D28: =IFERROR(__xludf.DUMMYFUNCTION("""COMPUTED_VALUE"""),1.0) -> 1 | F28: {=XLOOKUP($E28,'Player Database'!$B$2:$B252,'Player Database'!$K$2:$K252)} -> #N/A | G28: {=XLOOKUP($E28,'Player Database'!$B$2:$B252,'Player Database'!$AE$2:$AE252)} -> #N/A | H28: {=XLOOKUP($E28,'Player Database'!$B$2:$B252,'Player Database'!$H$2:$H252)} -> #N/A | I28: {=XLOOKUP($E28,'Player Database'!$B$2:$B252,'Player Database'!$O$2:$O252)} -> #N/A | J28: {=XLOOKUP($E28,'Player Database'!$B$2:$B252,'Player Database'!$P$2:$P252)} -> #N/A | K28: {=XLOOKUP($E28,'Player Database'!$B$2:$B252,'Player Database'!$U$2:$U252)} -> #N/A | L28: {=XLOOKUP($E28,'Player Database'!$B$2:$B252,'Player Database'!$W$2:$W252)} -> #N/A | M28: =CONCATENATE(O28," - ",P28) -> 0 - 0 | N28: {=IF(XLOOKUP($E28,'Player Database'!$B$2:$B252,'Player Database'!$AA$2:$AA252)="",XLOOKUP($E28,'Player Database'!$B$2:$B252,'Player Database'!$G$2:$G252),XLOOKUP($E28,'Player Database'!$B$2:$B252,'Player Database'!$AA$2:$AA252))} -> #N/A | O28: =COUNTIFs(Matches!$B:$B,E28,Matches!$A:$A,">"&Q28,Matches!$A:$A,"<"&R28) -> 0 | P28: =COUNTIFs(Matches!$C:$C,E28,Matches!$A:$A,">"&Q28,Matches!$A:$A,"<"&R28) -> 0 | Q28: =VLOOKUP($C$2,Quotas!$A$7:$E$14,2,FALSE) -> 46171.708 | R28: =VLOOKUP($C$2,Quotas!$A$7:$E$14,3,FALSE) -> 46178.708
A29: {=XLOOKUP($E29,'Player Database'!$B$2:$B252,'Player Database'!$C$2:$C252)} -> #N/A | B29: {=XLOOKUP($E29,'Player Database'!$B$2:$B252,'Player Database'!$E$2:$E252)} -> #N/A | C29: {=XLOOKUP($E29,'Player Database'!$B$2:$B252,'Player Database'!$F$2:$F252)} -> #N/A | D29: =IFERROR(__xludf.DUMMYFUNCTION("""COMPUTED_VALUE"""),1.0) -> 1 | F29: {=XLOOKUP($E29,'Player Database'!$B$2:$B252,'Player Database'!$K$2:$K252)} -> #N/A | G29: {=XLOOKUP($E29,'Player Database'!$B$2:$B252,'Player Database'!$AE$2:$AE252)} -> #N/A | H29: {=XLOOKUP($E29,'Player Database'!$B$2:$B252,'Player Database'!$H$2:$H252)} -> #N/A | I29: {=XLOOKUP($E29,'Player Database'!$B$2:$B252,'Player Database'!$O$2:$O252)} -> #N/A | J29: {=XLOOKUP($E29,'Player Database'!$B$2:$B252,'Player Database'!$P$2:$P252)} -> #N/A | K29: {=XLOOKUP($E29,'Player Database'!$B$2:$B252,'Player Database'!$U$2:$U252)} -> #N/A | L29: {=XLOOKUP($E29,'Player Database'!$B$2:$B252,'Player Database'!$W$2:$W252)} -> #N/A | M29: =CONCATENATE(O29," - ",P29) -> 0 - 0 | N29: {=IF(XLOOKUP($E29,'Player Database'!$B$2:$B252,'Player Database'!$AA$2:$AA252)="",XLOOKUP($E29,'Player Database'!$B$2:$B252,'Player Database'!$G$2:$G252),XLOOKUP($E29,'Player Database'!$B$2:$B252,'Player Database'!$AA$2:$AA252))} -> #N/A | O29: =COUNTIFs(Matches!$B:$B,E29,Matches!$A:$A,">"&Q29,Matches!$A:$A,"<"&R29) -> 0 | P29: =COUNTIFs(Matches!$C:$C,E29,Matches!$A:$A,">"&Q29,Matches!$A:$A,"<"&R29) -> 0 | Q29: =VLOOKUP($C$2,Quotas!$A$7:$E$14,2,FALSE) -> 46171.708 | R29: =VLOOKUP($C$2,Quotas!$A$7:$E$14,3,FALSE) -> 46178.708
A30: {=XLOOKUP($E30,'Player Database'!$B$2:$B252,'Player Database'!$C$2:$C252)} -> #N/A | B30: {=XLOOKUP($E30,'Player Database'!$B$2:$B252,'Player Database'!$E$2:$E252)} -> #N/A | C30: {=XLOOKUP($E30,'Player Database'!$B$2:$B252,'Player Database'!$F$2:$F252)} -> #N/A | D30: =IFERROR(__xludf.DUMMYFUNCTION("""COMPUTED_VALUE"""),1.0) -> 1 | F30: {=XLOOKUP($E30,'Player Database'!$B$2:$B252,'Player Database'!$K$2:$K252)} -> #N/A | G30: {=XLOOKUP($E30,'Player Database'!$B$2:$B252,'Player Database'!$AE$2:$AE252)} -> #N/A | H30: {=XLOOKUP($E30,'Player Database'!$B$2:$B252,'Player Database'!$H$2:$H252)} -> #N/A | I30: {=XLOOKUP($E30,'Player Database'!$B$2:$B252,'Player Database'!$O$2:$O252)} -> #N/A | J30: {=XLOOKUP($E30,'Player Database'!$B$2:$B252,'Player Database'!$P$2:$P252)} -> #N/A | K30: {=XLOOKUP($E30,'Player Database'!$B$2:$B252,'Player Database'!$U$2:$U252)} -> #N/A | L30: {=XLOOKUP($E30,'Player Database'!$B$2:$B252,'Player Database'!$W$2:$W252)} -> #N/A | M30: =CONCATENATE(O30," - ",P30) -> 0 - 0 | N30: {=IF(XLOOKUP($E30,'Player Database'!$B$2:$B252,'Player Database'!$AA$2:$AA252)="",XLOOKUP($E30,'Player Database'!$B$2:$B252,'Player Database'!$G$2:$G252),XLOOKUP($E30,'Player Database'!$B$2:$B252,'Player Database'!$AA$2:$AA252))} -> #N/A | O30: =COUNTIFs(Matches!$B:$B,E30,Matches!$A:$A,">"&Q30,Matches!$A:$A,"<"&R30) -> 0 | P30: =COUNTIFs(Matches!$C:$C,E30,Matches!$A:$A,">"&Q30,Matches!$A:$A,"<"&R30) -> 0 | Q30: =VLOOKUP($C$2,Quotas!$A$7:$E$14,2,FALSE) -> 46171.708 | R30: =VLOOKUP($C$2,Quotas!$A$7:$E$14,3,FALSE) -> 46178.708
A31: {=XLOOKUP($E31,'Player Database'!$B$2:$B252,'Player Database'!$C$2:$C252)} -> #N/A | B31: {=XLOOKUP($E31,'Player Database'!$B$2:$B252,'Player Database'!$E$2:$E252)} -> #N/A | C31: {=XLOOKUP($E31,'Player Database'!$B$2:$B252,'Player Database'!$F$2:$F252)} -> #N/A | D31: =IFERROR(__xludf.DUMMYFUNCTION("""COMPUTED_VALUE"""),1.0) -> 1 | F31: {=XLOOKUP($E31,'Player Database'!$B$2:$B252,'Player Database'!$K$2:$K252)} -> #N/A | G31: {=XLOOKUP($E31,'Player Database'!$B$2:$B252,'Player Database'!$AE$2:$AE252)} -> #N/A | H31: {=XLOOKUP($E31,'Player Database'!$B$2:$B252,'Player Database'!$H$2:$H252)} -> #N/A | I31: {=XLOOKUP($E31,'Player Database'!$B$2:$B252,'Player Database'!$O$2:$O252)} -> #N/A | J31: {=XLOOKUP($E31,'Player Database'!$B$2:$B252,'Player Database'!$P$2:$P252)} -> #N/A | K31: {=XLOOKUP($E31,'Player Database'!$B$2:$B252,'Player Database'!$U$2:$U252)} -> #N/A | L31: {=XLOOKUP($E31,'Player Database'!$B$2:$B252,'Player Database'!$W$2:$W252)} -> #N/A | M31: =CONCATENATE(O31," - ",P31) -> 0 - 0 | N31: {=IF(XLOOKUP($E31,'Player Database'!$B$2:$B252,'Player Database'!$AA$2:$AA252)="",XLOOKUP($E31,'Player Database'!$B$2:$B252,'Player Database'!$G$2:$G252),XLOOKUP($E31,'Player Database'!$B$2:$B252,'Player Database'!$AA$2:$AA252))} -> #N/A | O31: =COUNTIFs(Matches!$B:$B,E31,Matches!$A:$A,">"&Q31,Matches!$A:$A,"<"&R31) -> 0 | P31: =COUNTIFs(Matches!$C:$C,E31,Matches!$A:$A,">"&Q31,Matches!$A:$A,"<"&R31) -> 0 | Q31: =VLOOKUP($C$2,Quotas!$A$7:$E$14,2,FALSE) -> 46171.708 | R31: =VLOOKUP($C$2,Quotas!$A$7:$E$14,3,FALSE) -> 46178.708
A32: {=XLOOKUP($E32,'Player Database'!$B$2:$B252,'Player Database'!$C$2:$C252)} -> #N/A | B32: {=XLOOKUP($E32,'Player Database'!$B$2:$B252,'Player Database'!$E$2:$E252)} -> #N/A | C32: {=XLOOKUP($E32,'Player Database'!$B$2:$B252,'Player Database'!$F$2:$F252)} -> #N/A | D32: =IFERROR(__xludf.DUMMYFUNCTION("""COMPUTED_VALUE"""),1.0) -> 1 | F32: {=XLOOKUP($E32,'Player Database'!$B$2:$B252,'Player Database'!$K$2:$K252)} -> #N/A | G32: {=XLOOKUP($E32,'Player Database'!$B$2:$B252,'Player Database'!$AE$2:$AE252)} -> #N/A | H32: {=XLOOKUP($E32,'Player Database'!$B$2:$B252,'Player Database'!$H$2:$H252)} -> #N/A | I32: {=XLOOKUP($E32,'Player Database'!$B$2:$B252,'Player Database'!$O$2:$O252)} -> #N/A | J32: {=XLOOKUP($E32,'Player Database'!$B$2:$B252,'Player Database'!$P$2:$P252)} -> #N/A | K32: {=XLOOKUP($E32,'Player Database'!$B$2:$B252,'Player Database'!$U$2:$U252)} -> #N/A | L32: {=XLOOKUP($E32,'Player Database'!$B$2:$B252,'Player Database'!$W$2:$W252)} -> #N/A | M32: =CONCATENATE(O32," - ",P32) -> 0 - 0 | N32: {=IF(XLOOKUP($E32,'Player Database'!$B$2:$B252,'Player Database'!$AA$2:$AA252)="",XLOOKUP($E32,'Player Database'!$B$2:$B252,'Player Database'!$G$2:$G252),XLOOKUP($E32,'Player Database'!$B$2:$B252,'Player Database'!$AA$2:$AA252))} -> #N/A | O32: =COUNTIFs(Matches!$B:$B,E32,Matches!$A:$A,">"&Q32,Matches!$A:$A,"<"&R32) -> 0 | P32: =COUNTIFs(Matches!$C:$C,E32,Matches!$A:$A,">"&Q32,Matches!$A:$A,"<"&R32) -> 0 | Q32: =VLOOKUP($C$2,Quotas!$A$7:$E$14,2,FALSE) -> 46171.708 | R32: =VLOOKUP($C$2,Quotas!$A$7:$E$14,3,FALSE) -> 46178.708
A33: {=XLOOKUP($E33,'Player Database'!$B$2:$B252,'Player Database'!$C$2:$C252)} -> #N/A | B33: {=XLOOKUP($E33,'Player Database'!$B$2:$B252,'Player Database'!$E$2:$E252)} -> #N/A | C33: {=XLOOKUP($E33,'Player Database'!$B$2:$B252,'Player Database'!$F$2:$F252)} -> #N/A | D33: =IFERROR(__xludf.DUMMYFUNCTION("""COMPUTED_VALUE"""),1.0) -> 1 | F33: {=XLOOKUP($E33,'Player Database'!$B$2:$B252,'Player Database'!$K$2:$K252)} -> #N/A | G33: {=XLOOKUP($E33,'Player Database'!$B$2:$B252,'Player Database'!$AE$2:$AE252)} -> #N/A | H33: {=XLOOKUP($E33,'Player Database'!$B$2:$B252,'Player Database'!$H$2:$H252)} -> #N/A | I33: {=XLOOKUP($E33,'Player Database'!$B$2:$B252,'Player Database'!$O$2:$O252)} -> #N/A | J33: {=XLOOKUP($E33,'Player Database'!$B$2:$B252,'Player Database'!$P$2:$P252)} -> #N/A | K33: {=XLOOKUP($E33,'Player Database'!$B$2:$B252,'Player Database'!$U$2:$U252)} -> #N/A | L33: {=XLOOKUP($E33,'Player Database'!$B$2:$B252,'Player Database'!$W$2:$W252)} -> #N/A | M33: =CONCATENATE(O33," - ",P33) -> 0 - 0 | N33: {=IF(XLOOKUP($E33,'Player Database'!$B$2:$B252,'Player Database'!$AA$2:$AA252)="",XLOOKUP($E33,'Player Database'!$B$2:$B252,'Player Database'!$G$2:$G252),XLOOKUP($E33,'Player Database'!$B$2:$B252,'Player Database'!$AA$2:$AA252))} -> #N/A | O33: =COUNTIFs(Matches!$B:$B,E33,Matches!$A:$A,">"&Q33,Matches!$A:$A,"<"&R33) -> 0 | P33: =COUNTIFs(Matches!$C:$C,E33,Matches!$A:$A,">"&Q33,Matches!$A:$A,"<"&R33) -> 0 | Q33: =VLOOKUP($C$2,Quotas!$A$7:$E$14,2,FALSE) -> 46171.708 | R33: =VLOOKUP($C$2,Quotas!$A$7:$E$14,3,FALSE) -> 46178.708
A34: {=XLOOKUP($E34,'Player Database'!$B$2:$B252,'Player Database'!$C$2:$C252)} -> #N/A | B34: {=XLOOKUP($E34,'Player Database'!$B$2:$B252,'Player Database'!$E$2:$E252)} -> #N/A | C34: {=XLOOKUP($E34,'Player Database'!$B$2:$B252,'Player Database'!$F$2:$F252)} -> #N/A | D34: =IFERROR(__xludf.DUMMYFUNCTION("""COMPUTED_VALUE"""),1.0) -> 1 | F34: {=XLOOKUP($E34,'Player Database'!$B$2:$B252,'Player Database'!$K$2:$K252)} -> #N/A | G34: {=XLOOKUP($E34,'Player Database'!$B$2:$B252,'Player Database'!$AE$2:$AE252)} -> #N/A | H34: {=XLOOKUP($E34,'Player Database'!$B$2:$B252,'Player Database'!$H$2:$H252)} -> #N/A | I34: {=XLOOKUP($E34,'Player Database'!$B$2:$B252,'Player Database'!$O$2:$O252)} -> #N/A | J34: {=XLOOKUP($E34,'Player Database'!$B$2:$B252,'Player Database'!$P$2:$P252)} -> #N/A | K34: {=XLOOKUP($E34,'Player Database'!$B$2:$B252,'Player Database'!$U$2:$U252)} -> #N/A | L34: {=XLOOKUP($E34,'Player Database'!$B$2:$B252,'Player Database'!$W$2:$W252)} -> #N/A | M34: =CONCATENATE(O34," - ",P34) -> 0 - 0 | N34: {=IF(XLOOKUP($E34,'Player Database'!$B$2:$B252,'Player Database'!$AA$2:$AA252)="",XLOOKUP($E34,'Player Database'!$B$2:$B252,'Player Database'!$G$2:$G252),XLOOKUP($E34,'Player Database'!$B$2:$B252,'Player Database'!$AA$2:$AA252))} -> #N/A | O34: =COUNTIFs(Matches!$B:$B,E34,Matches!$A:$A,">"&Q34,Matches!$A:$A,"<"&R34) -> 0 | P34: =COUNTIFs(Matches!$C:$C,E34,Matches!$A:$A,">"&Q34,Matches!$A:$A,"<"&R34) -> 0 | Q34: =VLOOKUP($C$2,Quotas!$A$7:$E$14,2,FALSE) -> 46171.708 | R34: =VLOOKUP($C$2,Quotas!$A$7:$E$14,3,FALSE) -> 46178.708
A35: {=XLOOKUP($E35,'Player Database'!$B$2:$B252,'Player Database'!$C$2:$C252)} -> #N/A | B35: {=XLOOKUP($E35,'Player Database'!$B$2:$B252,'Player Database'!$E$2:$E252)} -> #N/A | C35: {=XLOOKUP($E35,'Player Database'!$B$2:$B252,'Player Database'!$F$2:$F252)} -> #N/A | D35: =IFERROR(__xludf.DUMMYFUNCTION("""COMPUTED_VALUE"""),1.0) -> 1 | F35: {=XLOOKUP($E35,'Player Database'!$B$2:$B252,'Player Database'!$K$2:$K252)} -> #N/A | G35: {=XLOOKUP($E35,'Player Database'!$B$2:$B252,'Player Database'!$AE$2:$AE252)} -> #N/A | H35: {=XLOOKUP($E35,'Player Database'!$B$2:$B252,'Player Database'!$H$2:$H252)} -> #N/A | I35: {=XLOOKUP($E35,'Player Database'!$B$2:$B252,'Player Database'!$O$2:$O252)} -> #N/A | J35: {=XLOOKUP($E35,'Player Database'!$B$2:$B252,'Player Database'!$P$2:$P252)} -> #N/A | K35: {=XLOOKUP($E35,'Player Database'!$B$2:$B252,'Player Database'!$U$2:$U252)} -> #N/A | L35: {=XLOOKUP($E35,'Player Database'!$B$2:$B252,'Player Database'!$W$2:$W252)} -> #N/A | M35: =CONCATENATE(O35," - ",P35) -> 0 - 0 | N35: {=IF(XLOOKUP($E35,'Player Database'!$B$2:$B252,'Player Database'!$AA$2:$AA252)="",XLOOKUP($E35,'Player Database'!$B$2:$B252,'Player Database'!$G$2:$G252),XLOOKUP($E35,'Player Database'!$B$2:$B252,'Player Database'!$AA$2:$AA252))} -> #N/A | O35: =COUNTIFs(Matches!$B:$B,E35,Matches!$A:$A,">"&Q35,Matches!$A:$A,"<"&R35) -> 0 | P35: =COUNTIFs(Matches!$C:$C,E35,Matches!$A:$A,">"&Q35,Matches!$A:$A,"<"&R35) -> 0 | Q35: =VLOOKUP($C$2,Quotas!$A$7:$E$14,2,FALSE) -> 46171.708 | R35: =VLOOKUP($C$2,Quotas!$A$7:$E$14,3,FALSE) -> 46178.708
A36: {=XLOOKUP($E36,'Player Database'!$B$2:$B252,'Player Database'!$C$2:$C252)} -> #N/A | B36: {=XLOOKUP($E36,'Player Database'!$B$2:$B252,'Player Database'!$E$2:$E252)} -> #N/A | C36: {=XLOOKUP($E36,'Player Database'!$B$2:$B252,'Player Database'!$F$2:$F252)} -> #N/A | D36: =IFERROR(__xludf.DUMMYFUNCTION("""COMPUTED_VALUE"""),1.0) -> 1 | F36: {=XLOOKUP($E36,'Player Database'!$B$2:$B252,'Player Database'!$K$2:$K252)} -> #N/A | G36: {=XLOOKUP($E36,'Player Database'!$B$2:$B252,'Player Database'!$AE$2:$AE252)} -> #N/A | H36: {=XLOOKUP($E36,'Player Database'!$B$2:$B252,'Player Database'!$H$2:$H252)} -> #N/A | I36: {=XLOOKUP($E36,'Player Database'!$B$2:$B252,'Player Database'!$O$2:$O252)} -> #N/A | J36: {=XLOOKUP($E36,'Player Database'!$B$2:$B252,'Player Database'!$P$2:$P252)} -> #N/A | K36: {=XLOOKUP($E36,'Player Database'!$B$2:$B252,'Player Database'!$U$2:$U252)} -> #N/A | L36: {=XLOOKUP($E36,'Player Database'!$B$2:$B252,'Player Database'!$W$2:$W252)} -> #N/A | M36: =CONCATENATE(O36," - ",P36) -> 0 - 0 | N36: {=IF(XLOOKUP($E36,'Player Database'!$B$2:$B252,'Player Database'!$AA$2:$AA252)="",XLOOKUP($E36,'Player Database'!$B$2:$B252,'Player Database'!$G$2:$G252),XLOOKUP($E36,'Player Database'!$B$2:$B252,'Player Database'!$AA$2:$AA252))} -> #N/A | O36: =COUNTIFs(Matches!$B:$B,E36,Matches!$A:$A,">"&Q36,Matches!$A:$A,"<"&R36) -> 0 | P36: =COUNTIFs(Matches!$C:$C,E36,Matches!$A:$A,">"&Q36,Matches!$A:$A,"<"&R36) -> 0 | Q36: =VLOOKUP($C$2,Quotas!$A$7:$E$14,2,FALSE) -> 46171.708 | R36: =VLOOKUP($C$2,Quotas!$A$7:$E$14,3,FALSE) -> 46178.708
A37: {=XLOOKUP($E37,'Player Database'!$B$2:$B252,'Player Database'!$C$2:$C252)} -> #N/A | B37: {=XLOOKUP($E37,'Player Database'!$B$2:$B252,'Player Database'!$E$2:$E252)} -> #N/A | C37: {=XLOOKUP($E37,'Player Database'!$B$2:$B252,'Player Database'!$F$2:$F252)} -> #N/A | D37: =IFERROR(__xludf.DUMMYFUNCTION("""COMPUTED_VALUE"""),1.0) -> 1 | F37: {=XLOOKUP($E37,'Player Database'!$B$2:$B252,'Player Database'!$K$2:$K252)} -> #N/A | G37: {=XLOOKUP($E37,'Player Database'!$B$2:$B252,'Player Database'!$AE$2:$AE252)} -> #N/A | H37: {=XLOOKUP($E37,'Player Database'!$B$2:$B252,'Player Database'!$H$2:$H252)} -> #N/A | I37: {=XLOOKUP($E37,'Player Database'!$B$2:$B252,'Player Database'!$O$2:$O252)} -> #N/A | J37: {=XLOOKUP($E37,'Player Database'!$B$2:$B252,'Player Database'!$P$2:$P252)} -> #N/A | K37: {=XLOOKUP($E37,'Player Database'!$B$2:$B252,'Player Database'!$U$2:$U252)} -> #N/A | L37: {=XLOOKUP($E37,'Player Database'!$B$2:$B252,'Player Database'!$W$2:$W252)} -> #N/A | M37: =CONCATENATE(O37," - ",P37) -> 0 - 0 | N37: {=IF(XLOOKUP($E37,'Player Database'!$B$2:$B252,'Player Database'!$AA$2:$AA252)="",XLOOKUP($E37,'Player Database'!$B$2:$B252,'Player Database'!$G$2:$G252),XLOOKUP($E37,'Player Database'!$B$2:$B252,'Player Database'!$AA$2:$AA252))} -> #N/A | O37: =COUNTIFs(Matches!$B:$B,E37,Matches!$A:$A,">"&Q37,Matches!$A:$A,"<"&R37) -> 0 | P37: =COUNTIFs(Matches!$C:$C,E37,Matches!$A:$A,">"&Q37,Matches!$A:$A,"<"&R37) -> 0 | Q37: =VLOOKUP($C$2,Quotas!$A$7:$E$14,2,FALSE) -> 46171.708 | R37: =VLOOKUP($C$2,Quotas!$A$7:$E$14,3,FALSE) -> 46178.708
A38: {=XLOOKUP($E38,'Player Database'!$B$2:$B252,'Player Database'!$C$2:$C252)} -> #N/A | B38: {=XLOOKUP($E38,'Player Database'!$B$2:$B252,'Player Database'!$E$2:$E252)} -> #N/A | C38: {=XLOOKUP($E38,'Player Database'!$B$2:$B252,'Player Database'!$F$2:$F252)} -> #N/A | D38: =IFERROR(__xludf.DUMMYFUNCTION("""COMPUTED_VALUE"""),1.0) -> 1 | F38: {=XLOOKUP($E38,'Player Database'!$B$2:$B252,'Player Database'!$K$2:$K252)} -> #N/A | G38: {=XLOOKUP($E38,'Player Database'!$B$2:$B252,'Player Database'!$AE$2:$AE252)} -> #N/A | H38: {=XLOOKUP($E38,'Player Database'!$B$2:$B252,'Player Database'!$H$2:$H252)} -> #N/A | I38: {=XLOOKUP($E38,'Player Database'!$B$2:$B252,'Player Database'!$O$2:$O252)} -> #N/A | J38: {=XLOOKUP($E38,'Player Database'!$B$2:$B252,'Player Database'!$P$2:$P252)} -> #N/A | K38: {=XLOOKUP($E38,'Player Database'!$B$2:$B252,'Player Database'!$U$2:$U252)} -> #N/A | L38: {=XLOOKUP($E38,'Player Database'!$B$2:$B252,'Player Database'!$W$2:$W252)} -> #N/A | M38: =CONCATENATE(O38," - ",P38) -> 0 - 0 | N38: {=IF(XLOOKUP($E38,'Player Database'!$B$2:$B252,'Player Database'!$AA$2:$AA252)="",XLOOKUP($E38,'Player Database'!$B$2:$B252,'Player Database'!$G$2:$G252),XLOOKUP($E38,'Player Database'!$B$2:$B252,'Player Database'!$AA$2:$AA252))} -> #N/A | O38: =COUNTIFs(Matches!$B:$B,E38,Matches!$A:$A,">"&Q38,Matches!$A:$A,"<"&R38) -> 0 | P38: =COUNTIFs(Matches!$C:$C,E38,Matches!$A:$A,">"&Q38,Matches!$A:$A,"<"&R38) -> 0 | Q38: =VLOOKUP($C$2,Quotas!$A$7:$E$14,2,FALSE) -> 46171.708 | R38: =VLOOKUP($C$2,Quotas!$A$7:$E$14,3,FALSE) -> 46178.708
A39: {=XLOOKUP($E39,'Player Database'!$B$2:$B252,'Player Database'!$C$2:$C252)} -> #N/A | B39: {=XLOOKUP($E39,'Player Database'!$B$2:$B252,'Player Database'!$E$2:$E252)} -> #N/A | C39: {=XLOOKUP($E39,'Player Database'!$B$2:$B252,'Player Database'!$F$2:$F252)} -> #N/A | D39: =IFERROR(__xludf.DUMMYFUNCTION("""COMPUTED_VALUE"""),1.0) -> 1 | F39: {=XLOOKUP($E39,'Player Database'!$B$2:$B252,'Player Database'!$K$2:$K252)} -> #N/A | G39: {=XLOOKUP($E39,'Player Database'!$B$2:$B252,'Player Database'!$AE$2:$AE252)} -> #N/A | H39: {=XLOOKUP($E39,'Player Database'!$B$2:$B252,'Player Database'!$H$2:$H252)} -> #N/A | I39: {=XLOOKUP($E39,'Player Database'!$B$2:$B252,'Player Database'!$O$2:$O252)} -> #N/A | J39: {=XLOOKUP($E39,'Player Database'!$B$2:$B252,'Player Database'!$P$2:$P252)} -> #N/A | K39: {=XLOOKUP($E39,'Player Database'!$B$2:$B252,'Player Database'!$U$2:$U252)} -> #N/A | L39: {=XLOOKUP($E39,'Player Database'!$B$2:$B252,'Player Database'!$W$2:$W252)} -> #N/A | M39: =CONCATENATE(O39," - ",P39) -> 0 - 0 | N39: {=IF(XLOOKUP($E39,'Player Database'!$B$2:$B252,'Player Database'!$AA$2:$AA252)="",XLOOKUP($E39,'Player Database'!$B$2:$B252,'Player Database'!$G$2:$G252),XLOOKUP($E39,'Player Database'!$B$2:$B252,'Player Database'!$AA$2:$AA252))} -> #N/A | O39: =COUNTIFs(Matches!$B:$B,E39,Matches!$A:$A,">"&Q39,Matches!$A:$A,"<"&R39) -> 0 | P39: =COUNTIFs(Matches!$C:$C,E39,Matches!$A:$A,">"&Q39,Matches!$A:$A,"<"&R39) -> 0 | Q39: =VLOOKUP($C$2,Quotas!$A$7:$E$14,2,FALSE) -> 46171.708 | R39: =VLOOKUP($C$2,Quotas!$A$7:$E$14,3,FALSE) -> 46178.708
