Workbook

Sheet BotStuff
A1: Choice State: | B1: {} | Z1: Survey Sent?

Sheet Combined Standings
A1: ARENA GAUNTLET LEAGUE: Marvel Super Heroes
A2: Week: | C2: =Quotas!B2 -> 3
A3: PLAYER NAME | B3: ARENA ID | C3: COUNTRY | D3: RANK | E3: Player Name & ID | F3: RECORD | G3: MATCHES PLAYED | H3: MATCHES <Min | I3: MATCHES <Max | J3: OMW% | K3: HERO SCORE | L3: MATCHES TO PLAY STATUS | M3: THIS WEEK | N3: OTHER INFO | O3: wins this week | P3: losses this week | Q3: Time min | R3: Time max
A4: {=XLOOKUP($E4,'Player Database'!$B$2:$B758,'Player Database'!$C$2:$C758)} -> #N/A | B4: {=XLOOKUP($E4,'Player Database'!$B$2:$B758,'Player Database'!$E$2:$E758)} -> #N/A | C4: {=XLOOKUP($E4,'Player Database'!$B$2:$B758,'Player Database'!$F$2:$F758)} -> #N/A | D4: =IFERROR(__xludf.DUMMYFUNCTION("QUERY('Player Database'!A2:B173,""SELECT A,B WHERE B != ' - ' ORDER BY A"")"),1.0) -> 1 | E4: =IFERROR(__xludf.DUMMYFUNCTION("""COMPUTED_VALUE"""),"#REF!") -> #REF! | F4: {=XLOOKUP($E4,'Player Database'!$B$2:$B758,'Player Database'!$K$2:$K758)} -> #N/A | G4: {=XLOOKUP($E4,'Player Database'!$B$2:$B758,'Player Database'!$H$2:$H758)} -> #N/A | H4: {=XLOOKUP($E4,'Player Database'!$B$2:$B758,'Player Database'!$O$2:$O758)} -> #N/A | I4: {=XLOOKUP($E4,'Player Database'!$B$2:$B758,'Player Database'!$P$2:$P758)} -> #N/A | J4: {=XLOOKUP($E4,'Player Database'!$B$2:$B758,'Player Database'!$U$2:$U758)} -> #N/A | K4: =VLOOKUP(E4, 'Player Database'!B:AE, 30, FALSE) -> #N/A | L4: {=XLOOKUP($E4,'Player Database'!$B$2:$B758,'Player Database'!$W$2:$W758)} -> #N/A | M4: =CONCATENATE(O4," - ",P4) -> 0 - 0 | N4: {=IF(XLOOKUP($E4,'Player Database'!$B$2:$B758,'Player Database'!$AA$2:$AA758)="",XLOOKUP($E4,'Player Database'!$B$2:$B758,'Player Database'!$G$2:$G758),XLOOKUP($E4,'Player Database'!$B$2:$B758,'Player Database'!$AA$2:$AA758))} -> #N/A | O4: =COUNTIFs(Matches!$B:$B,E4,Matches!$A:$A,">"&Q4,Matches!$A:$A,"<"&R4) -> 0 | P4: =COUNTIFs(Matches!$C:$C,E4,Matches!$A:$A,">"&Q4,Matches!$A:$A,"<"&R4) -> 0 | Q4: =VLOOKUP($C$2,Quotas!$A$7:$E$14,2,FALSE) -> 46213.708 | R4: =VLOOKUP($C$2,Quotas!$A$7:$E$14,3,FALSE) -> 46220.708
A5: {=XLOOKUP($E5,'Player Database'!$B$2:$B758,'Player Database'!$C$2:$C758)} -> #N/A | B5: {=XLOOKUP($E5,'Player Database'!$B$2:$B758,'Player Database'!$E$2:$E758)} -> #N/A | C5: {=XLOOKUP($E5,'Player Database'!$B$2:$B758,'Player Database'!$F$2:$F758)} -> #N/A | D5: =IFERROR(__xludf.DUMMYFUNCTION("""COMPUTED_VALUE"""),1.0) -> 1 | F5: {=XLOOKUP($E5,'Player Database'!$B$2:$B758,'Player Database'!$K$2:$K758)} -> #N/A | G5: {=XLOOKUP($E5,'Player Database'!$B$2:$B758,'Player Database'!$H$2:$H758)} -> #N/A | H5: {=XLOOKUP($E5,'Player Database'!$B$2:$B758,'Player Database'!$O$2:$O758)} -> #N/A | I5: {=XLOOKUP($E5,'Player Database'!$B$2:$B758,'Player Database'!$P$2:$P758)} -> #N/A | J5: {=XLOOKUP($E5,'Player Database'!$B$2:$B758,'Player Database'!$U$2:$U758)} -> #N/A | K5: =VLOOKUP(E5, 'Player Database'!B:AE, 30, FALSE) -> #N/A | L5: {=XLOOKUP($E5,'Player Database'!$B$2:$B758,'Player Database'!$W$2:$W758)} -> #N/A | M5: =CONCATENATE(O5," - ",P5) -> 0 - 0 | N5: {=IF(XLOOKUP($E5,'Player Database'!$B$2:$B758,'Player Database'!$AA$2:$AA758)="",XLOOKUP($E5,'Player Database'!$B$2:$B758,'Player Database'!$G$2:$G758),XLOOKUP($E5,'Player Database'!$B$2:$B758,'Player Database'!$AA$2:$AA758))} -> #N/A | O5: =COUNTIFs(Matches!$B:$B,E5,Matches!$A:$A,">"&Q5,Matches!$A:$A,"<"&R5) -> 0 | P5: =COUNTIFs(Matches!$C:$C,E5,Matches!$A:$A,">"&Q5,Matches!$A:$A,"<"&R5) -> 0 | Q5: =VLOOKUP($C$2,Quotas!$A$7:$E$14,2,FALSE) -> 46213.708 | R5: =VLOOKUP($C$2,Quotas!$A$7:$E$14,3,FALSE) -> 46220.708
A6: {=XLOOKUP($E6,'Player Database'!$B$2:$B758,'Player Database'!$C$2:$C758)} -> #N/A | B6: {=XLOOKUP($E6,'Player Database'!$B$2:$B758,'Player Database'!$E$2:$E758)} -> #N/A | C6: {=XLOOKUP($E6,'Player Database'!$B$2:$B758,'Player Database'!$F$2:$F758)} -> #N/A | D6: =IFERROR(__xludf.DUMMYFUNCTION("""COMPUTED_VALUE"""),1.0) -> 1 | F6: {=XLOOKUP($E6,'Player Database'!$B$2:$B758,'Player Database'!$K$2:$K758)} -> #N/A | G6: {=XLOOKUP($E6,'Player Database'!$B$2:$B758,'Player Database'!$H$2:$H758)} -> #N/A | H6: {=XLOOKUP($E6,'Player Database'!$B$2:$B758,'Player Database'!$O$2:$O758)} -> #N/A | I6: {=XLOOKUP($E6,'Player Database'!$B$2:$B758,'Player Database'!$P$2:$P758)} -> #N/A | J6: {=XLOOKUP($E6,'Player Database'!$B$2:$B758,'Player Database'!$U$2:$U758)} -> #N/A | K6: =VLOOKUP(E6, 'Player Database'!B:AE, 30, FALSE) -> #N/A | L6: {=XLOOKUP($E6,'Player Database'!$B$2:$B758,'Player Database'!$W$2:$W758)} -> #N/A | M6: =CONCATENATE(O6," - ",P6) -> 0 - 0 | N6: {=IF(XLOOKUP($E6,'Player Database'!$B$2:$B758,'Player Database'!$AA$2:$AA758)="",XLOOKUP($E6,'Player Database'!$B$2:$B758,'Player Database'!$G$2:$G758),XLOOKUP($E6,'Player Database'!$B$2:$B758,'Player Database'!$AA$2:$AA758))} -> #N/A | O6: =COUNTIFs(Matches!$B:$B,E6,Matches!$A:$A,">"&Q6,Matches!$A:$A,"<"&R6) -> 0 | P6: =COUNTIFs(Matches!$C:$C,E6,Matches!$A:$A,">"&Q6,Matches!$A:$A,"<"&R6) -> 0 | Q6: =VLOOKUP($C$2,Quotas!$A$7:$E$14,2,FALSE) -> 46213.708 | R6: =VLOOKUP($C$2,Quotas!$A$7:$E$14,3,FALSE) -> 46220.708
A7: {=XLOOKUP($E7,'Player Database'!$B$2:$B758,'Player Database'!$C$2:$C758)} -> #N/A | B7: {=XLOOKUP($E7,'Player Database'!$B$2:$B758,'Player Database'!$E$2:$E758)} -> #N/A | C7: {=XLOOKUP($E7,'Player Database'!$B$2:$B758,'Player Database'!$F$2:$F758)} -> #N/A | D7: =IFERROR(__xludf.DUMMYFUNCTION("""COMPUTED_VALUE"""),1.0) -> 1 | F7: {=XLOOKUP($E7,'Player Database'!$B$2:$B758,'Player Database'!$K$2:$K758)} -> #N/A | G7: {=XLOOKUP($E7,'Player Database'!$B$2:$B758,'Player Database'!$H$2:$H758)} -> #N/A | H7: {=XLOOKUP($E7,'Player Database'!$B$2:$B758,'Player Database'!$O$2:$O758)} -> #N/A | I7: {=XLOOKUP($E7,'Player Database'!$B$2:$B758,'Player Database'!$P$2:$P758)} -> #N/A | J7: {=XLOOKUP($E7,'Player Database'!$B$2:$B758,'Player Database'!$U$2:$U758)} -> #N/A | K7: =VLOOKUP(E7, 'Player Database'!B:AE, 30, FALSE) -> #N/A | L7: {=XLOOKUP($E7,'Player Database'!$B$2:$B758,'Player Database'!$W$2:$W758)} -> #N/A | M7: =CONCATENATE(O7," - ",P7) -> 0 - 0 | N7: {=IF(XLOOKUP($E7,'Player Database'!$B$2:$B758,'Player Database'!$AA$2:$AA758)="",XLOOKUP($E7,'Player Database'!$B$2:$B758,'Player Database'!$G$2:$G758),XLOOKUP($E7,'Player Database'!$B$2:$B758,'Player Database'!$AA$2:$AA758))} -> #N/A | O7: =COUNTIFs(Matches!$B:$B,E7,Matches!$A:$A,">"&Q7,Matches!$A:$A,"<"&R7) -> 0 | P7: =COUNTIFs(Matches!$C:$C,E7,Matches!$A:$A,">"&Q7,Matches!$A:$A,"<"&R7) -> 0 | Q7: =VLOOKUP($C$2,Quotas!$A$7:$E$14,2,FALSE) -> 46213.708 | R7: =VLOOKUP($C$2,Quotas!$A$7:$E$14,3,FALSE) -> 46220.708
A8: {=XLOOKUP($E8,'Player Database'!$B$2:$B758,'Player Database'!$C$2:$C758)} -> #N/A | B8: {=XLOOKUP($E8,'Player Database'!$B$2:$B758,'Player Database'!$E$2:$E758)} -> #N/A | C8: {=XLOOKUP($E8,'Player Database'!$B$2:$B758,'Player Database'!$F$2:$F758)} -> #N/A | D8: =IFERROR(__xludf.DUMMYFUNCTION("""COMPUTED_VALUE"""),1.0) -> 1 | F8: {=XLOOKUP($E8,'Player Database'!$B$2:$B758,'Player Database'!$K$2:$K758)} -> #N/A | G8: {=XLOOKUP($E8,'Player Database'!$B$2:$B758,'Player Database'!$H$2:$H758)} -> #N/A | H8: {=XLOOKUP($E8,'Player Database'!$B$2:$B758,'Player Database'!$O$2:$O758)} -> #N/A | I8: {=XLOOKUP($E8,'Player Database'!$B$2:$B758,'Player Database'!$P$2:$P758)} -> #N/A | J8: {=XLOOKUP($E8,'Player Database'!$B$2:$B758,'Player Database'!$U$2:$U758)} -> #N/A | K8: =VLOOKUP(E8, 'Player Database'!B:AE, 30, FALSE) -> #N/A | L8: {=XLOOKUP($E8,'Player Database'!$B$2:$B758,'Player Database'!$W$2:$W758)} -> #N/A | M8: =CONCATENATE(O8," - ",P8) -> 0 - 0 | N8: {=IF(XLOOKUP($E8,'Player Database'!$B$2:$B758,'Player Database'!$AA$2:$AA758)="",XLOOKUP($E8,'Player Database'!$B$2:$B758,'Player Database'!$G$2:$G758),XLOOKUP($E8,'Player Database'!$B$2:$B758,'Player Database'!$AA$2:$AA758))} -> #N/A | O8: =COUNTIFs(Matches!$B:$B,E8,Matches!$A:$A,">"&Q8,Matches!$A:$A,"<"&R8) -> 0 | P8: =COUNTIFs(Matches!$C:$C,E8,Matches!$A:$A,">"&Q8,Matches!$A:$A,"<"&R8) -> 0 | Q8: =VLOOKUP($C$2,Quotas!$A$7:$E$14,2,FALSE) -> 46213.708 | R8: =VLOOKUP($C$2,Quotas!$A$7:$E$14,3,FALSE) -> 46220.708
A9: {=XLOOKUP($E9,'Player Database'!$B$2:$B758,'Player Database'!$C$2:$C758)} -> #N/A | B9: {=XLOOKUP($E9,'Player Database'!$B$2:$B758,'Player Database'!$E$2:$E758)} -> #N/A | C9: {=XLOOKUP($E9,'Player Database'!$B$2:$B758,'Player Database'!$F$2:$F758)} -> #N/A | D9: =IFERROR(__xludf.DUMMYFUNCTION("""COMPUTED_VALUE"""),1.0) -> 1 | F9: {=XLOOKUP($E9,'Player Database'!$B$2:$B758,'Player Database'!$K$2:$K758)} -> #N/A | G9: {=XLOOKUP($E9,'Player Database'!$B$2:$B758,'Player Database'!$H$2:$H758)} -> #N/A | H9: {=XLOOKUP($E9,'Player Database'!$B$2:$B758,'Player Database'!$O$2:$O758)} -> #N/A | I9: {=XLOOKUP($E9,'Player Database'!$B$2:$B758,'Player Database'!$P$2:$P758)} -> #N/A | J9: {=XLOOKUP($E9,'Player Database'!$B$2:$B758,'Player Database'!$U$2:$U758)} -> #N/A | K9: =VLOOKUP(E9, 'Player Database'!B:AE, 30, FALSE) -> #N/A | L9: {=XLOOKUP($E9,'Player Database'!$B$2:$B758,'Player Database'!$W$2:$W758)} -> #N/A | M9: =CONCATENATE(O9," - ",P9) -> 0 - 0 | N9: {=IF(XLOOKUP($E9,'Player Database'!$B$2:$B758,'Player Database'!$AA$2:$AA758)="",XLOOKUP($E9,'Player Database'!$B$2:$B758,'Player Database'!$G$2:$G758),XLOOKUP($E9,'Player Database'!$B$2:$B758,'Player Database'!$AA$2:$AA758))} -> #N/A | O9: =COUNTIFs(Matches!$B:$B,E9,Matches!$A:$A,">"&Q9,Matches!$A:$A,"<"&R9) -> 0 | P9: =COUNTIFs(Matches!$C:$C,E9,Matches!$A:$A,">"&Q9,Matches!$A:$A,"<"&R9) -> 0 | Q9: =VLOOKUP($C$2,Quotas!$A$7:$E$14,2,FALSE) -> 46213.708 | R9: =VLOOKUP($C$2,Quotas!$A$7:$E$14,3,FALSE) -> 46220.708
A10: {=XLOOKUP($E10,'Player Database'!$B$2:$B758,'Player Database'!$C$2:$C758)} -> #N/A | B10: {=XLOOKUP($E10,'Player Database'!$B$2:$B758,'Player Database'!$E$2:$E758)} -> #N/A | C10: {=XLOOKUP($E10,'Player Database'!$B$2:$B758,'Player Database'!$F$2:$F758)} -> #N/A | D10: =IFERROR(__xludf.DUMMYFUNCTION("""COMPUTED_VALUE"""),1.0) -> 1 | F10: {=XLOOKUP($E10,'Player Database'!$B$2:$B758,'Player Database'!$K$2:$K758)} -> #N/A | G10: {=XLOOKUP($E10,'Player Database'!$B$2:$B758,'Player Database'!$H$2:$H758)} -> #N/A | H10: {=XLOOKUP($E10,'Player Database'!$B$2:$B758,'Player Database'!$O$2:$O758)} -> #N/A | I10: {=XLOOKUP($E10,'Player Database'!$B$2:$B758,'Player Database'!$P$2:$P758)} -> #N/A | J10: {=XLOOKUP($E10,'Player Database'!$B$2:$B758,'Player Database'!$U$2:$U758)} -> #N/A | K10: =VLOOKUP(E10, 'Player Database'!B:AE, 30, FALSE) -> #N/A | L10: {=XLOOKUP($E10,'Player Database'!$B$2:$B758,'Player Database'!$W$2:$W758)} -> #N/A | M10: =CONCATENATE(O10," - ",P10) -> 0 - 0 | N10: {=IF(XLOOKUP($E10,'Player Database'!$B$2:$B758,'Player Database'!$AA$2:$AA758)="",XLOOKUP($E10,'Player Database'!$B$2:$B758,'Player Database'!$G$2:$G758),XLOOKUP($E10,'Player Database'!$B$2:$B758,'Player Database'!$AA$2:$AA758))} -> #N/A | O10: =COUNTIFs(Matches!$B:$B,E10,Matches!$A:$A,">"&Q10,Matches!$A:$A,"<"&R10) -> 0 | P10: =COUNTIFs(Matches!$C:$C,E10,Matches!$A:$A,">"&Q10,Matches!$A:$A,"<"&R10) -> 0 | Q10: =VLOOKUP($C$2,Quotas!$A$7:$E$14,2,FALSE) -> 46213.708 | R10: =VLOOKUP($C$2,Quotas!$A$7:$E$14,3,FALSE) -> 46220.708
A11: {=XLOOKUP($E11,'Player Database'!$B$2:$B758,'Player Database'!$C$2:$C758)} -> #N/A | B11: {=XLOOKUP($E11,'Player Database'!$B$2:$B758,'Player Database'!$E$2:$E758)} -> #N/A | C11: {=XLOOKUP($E11,'Player Database'!$B$2:$B758,'Player Database'!$F$2:$F758)} -> #N/A | D11: =IFERROR(__xludf.DUMMYFUNCTION("""COMPUTED_VALUE"""),1.0) -> 1 | F11: {=XLOOKUP($E11,'Player Database'!$B$2:$B758,'Player Database'!$K$2:$K758)} -> #N/A | G11: {=XLOOKUP($E11,'Player Database'!$B$2:$B758,'Player Database'!$H$2:$H758)} -> #N/A | H11: {=XLOOKUP($E11,'Player Database'!$B$2:$B758,'Player Database'!$O$2:$O758)} -> #N/A | I11: {=XLOOKUP($E11,'Player Database'!$B$2:$B758,'Player Database'!$P$2:$P758)} -> #N/A | J11: {=XLOOKUP($E11,'Player Database'!$B$2:$B758,'Player Database'!$U$2:$U758)} -> #N/A | K11: =VLOOKUP(E11, 'Player Database'!B:AE, 30, FALSE) -> #N/A | L11: {=XLOOKUP($E11,'Player Database'!$B$2:$B758,'Player Database'!$W$2:$W758)} -> #N/A | M11: =CONCATENATE(O11," - ",P11) -> 0 - 0 | N11: {=IF(XLOOKUP($E11,'Player Database'!$B$2:$B758,'Player Database'!$AA$2:$AA758)="",XLOOKUP($E11,'Player Database'!$B$2:$B758,'Player Database'!$G$2:$G758),XLOOKUP($E11,'Player Database'!$B$2:$B758,'Player Database'!$AA$2:$AA758))} -> #N/A | O11: =COUNTIFs(Matches!$B:$B,E11,Matches!$A:$A,">"&Q11,Matches!$A:$A,"<"&R11) -> 0 | P11: =COUNTIFs(Matches!$C:$C,E11,Matches!$A:$A,">"&Q11,Matches!$A:$A,"<"&R11) -> 0 | Q11: =VLOOKUP($C$2,Quotas!$A$7:$E$14,2,FALSE) -> 46213.708 | R11: =VLOOKUP($C$2,Quotas!$A$7:$E$14,3,FALSE) -> 46220.708
A12: {=XLOOKUP($E12,'Player Database'!$B$2:$B758,'Player Database'!$C$2:$C758)} -> #N/A | B12: {=XLOOKUP($E12,'Player Database'!$B$2:$B758,'Player Database'!$E$2:$E758)} -> #N/A | C12: {=XLOOKUP($E12,'Player Database'!$B$2:$B758,'Player Database'!$F$2:$F758)} -> #N/A | D12: =IFERROR(__xludf.DUMMYFUNCTION("""COMPUTED_VALUE"""),1.0) -> 1 | F12: {=XLOOKUP($E12,'Player Database'!$B$2:$B758,'Player Database'!$K$2:$K758)} -> #N/A | G12: {=XLOOKUP($E12,'Player Database'!$B$2:$B758,'Player Database'!$H$2:$H758)} -> #N/A | H12: {=XLOOKUP($E12,'Player Database'!$B$2:$B758,'Player Database'!$O$2:$O758)} -> #N/A | I12: {=XLOOKUP($E12,'Player Database'!$B$2:$B758,'Player Database'!$P$2:$P758)} -> #N/A | J12: {=XLOOKUP($E12,'Player Database'!$B$2:$B758,'Player Database'!$U$2:$U758)} -> #N/A | K12: =VLOOKUP(E12, 'Player Database'!B:AE, 30, FALSE) -> #N/A | L12: {=XLOOKUP($E12,'Player Database'!$B$2:$B758,'Player Database'!$W$2:$W758)} -> #N/A | M12: =CONCATENATE(O12," - ",P12) -> 0 - 0 | N12: {=IF(XLOOKUP($E12,'Player Database'!$B$2:$B758,'Player Database'!$AA$2:$AA758)="",XLOOKUP($E12,'Player Database'!$B$2:$B758,'Player Database'!$G$2:$G758),XLOOKUP($E12,'Player Database'!$B$2:$B758,'Player Database'!$AA$2:$AA758))} -> #N/A | O12: =COUNTIFs(Matches!$B:$B,E12,Matches!$A:$A,">"&Q12,Matches!$A:$A,"<"&R12) -> 0 | P12: =COUNTIFs(Matches!$C:$C,E12,Matches!$A:$A,">"&Q12,Matches!$A:$A,"<"&R12) -> 0 | Q12: =VLOOKUP($C$2,Quotas!$A$7:$E$14,2,FALSE) -> 46213.708 | R12: =VLOOKUP($C$2,Quotas!$A$7:$E$14,3,FALSE) -> 46220.708
A13: {=XLOOKUP($E13,'Player Database'!$B$2:$B758,'Player Database'!$C$2:$C758)} -> #N/A | B13: {=XLOOKUP($E13,'Player Database'!$B$2:$B758,'Player Database'!$E$2:$E758)} -> #N/A | C13: {=XLOOKUP($E13,'Player Database'!$B$2:$B758,'Player Database'!$F$2:$F758)} -> #N/A | D13: =IFERROR(__xludf.DUMMYFUNCTION("""COMPUTED_VALUE"""),1.0) -> 1 | F13: {=XLOOKUP($E13,'Player Database'!$B$2:$B758,'Player Database'!$K$2:$K758)} -> #N/A | G13: {=XLOOKUP($E13,'Player Database'!$B$2:$B758,'Player Database'!$H$2:$H758)} -> #N/A | H13: {=XLOOKUP($E13,'Player Database'!$B$2:$B758,'Player Database'!$O$2:$O758)} -> #N/A | I13: {=XLOOKUP($E13,'Player Database'!$B$2:$B758,'Player Database'!$P$2:$P758)} -> #N/A | J13: {=XLOOKUP($E13,'Player Database'!$B$2:$B758,'Player Database'!$U$2:$U758)} -> #N/A | K13: =VLOOKUP(E13, 'Player Database'!B:AE, 30, FALSE) -> #N/A | L13: {=XLOOKUP($E13,'Player Database'!$B$2:$B758,'Player Database'!$W$2:$W758)} -> #N/A | M13: =CONCATENATE(O13," - ",P13) -> 0 - 0 | N13: {=IF(XLOOKUP($E13,'Player Database'!$B$2:$B758,'Player Database'!$AA$2:$AA758)="",XLOOKUP($E13,'Player Database'!$B$2:$B758,'Player Database'!$G$2:$G758),XLOOKUP($E13,'Player Database'!$B$2:$B758,'Player Database'!$AA$2:$AA758))} -> #N/A | O13: =COUNTIFs(Matches!$B:$B,E13,Matches!$A:$A,">"&Q13,Matches!$A:$A,"<"&R13) -> 0 | P13: =COUNTIFs(Matches!$C:$C,E13,Matches!$A:$A,">"&Q13,Matches!$A:$A,"<"&R13) -> 0 | Q13: =VLOOKUP($C$2,Quotas!$A$7:$E$14,2,FALSE) -> 46213.708 | R13: =VLOOKUP($C$2,Quotas!$A$7:$E$14,3,FALSE) -> 46220.708
A14: {=XLOOKUP($E14,'Player Database'!$B$2:$B758,'Player Database'!$C$2:$C758)} -> #N/A | B14: {=XLOOKUP($E14,'Player Database'!$B$2:$B758,'Player Database'!$E$2:$E758)} -> #N/A | C14: {=XLOOKUP($E14,'Player Database'!$B$2:$B758,'Player Database'!$F$2:$F758)} -> #N/A | D14: =IFERROR(__xludf.DUMMYFUNCTION("""COMPUTED_VALUE"""),1.0) -> 1 | F14: {=XLOOKUP($E14,'Player Database'!$B$2:$B758,'Player Database'!$K$2:$K758)} -> #N/A | G14: {=XLOOKUP($E14,'Player Database'!$B$2:$B758,'Player Database'!$H$2:$H758)} -> #N/A | H14: {=XLOOKUP($E14,'Player Database'!$B$2:$B758,'Player Database'!$O$2:$O758)} -> #N/A | I14: {=XLOOKUP($E14,'Player Database'!$B$2:$B758,'Player Database'!$P$2:$P758)} -> #N/A | J14: {=XLOOKUP($E14,'Player Database'!$B$2:$B758,'Player Database'!$U$2:$U758)} -> #N/A | K14: =VLOOKUP(E14, 'Player Database'!B:AE, 30, FALSE) -> #N/A | L14: {=XLOOKUP($E14,'Player Database'!$B$2:$B758,'Player Database'!$W$2:$W758)} -> #N/A | M14: =CONCATENATE(O14," - ",P14) -> 0 - 0 | N14: {=IF(XLOOKUP($E14,'Player Database'!$B$2:$B758,'Player Database'!$AA$2:$AA758)="",XLOOKUP($E14,'Player Database'!$B$2:$B758,'Player Database'!$G$2:$G758),XLOOKUP($E14,'Player Database'!$B$2:$B758,'Player Database'!$AA$2:$AA758))} -> #N/A | O14: =COUNTIFs(Matches!$B:$B,E14,Matches!$A:$A,">"&Q14,Matches!$A:$A,"<"&R14) -> 0 | P14: =COUNTIFs(Matches!$C:$C,E14,Matches!$A:$A,">"&Q14,Matches!$A:$A,"<"&R14) -> 0 | Q14: =VLOOKUP($C$2,Quotas!$A$7:$E$14,2,FALSE) -> 46213.708 | R14: =VLOOKUP($C$2,Quotas!$A$7:$E$14,3,FALSE) -> 46220.708
A15: {=XLOOKUP($E15,'Player Database'!$B$2:$B758,'Player Database'!$C$2:$C758)} -> #N/A | B15: {=XLOOKUP($E15,'Player Database'!$B$2:$B758,'Player Database'!$E$2:$E758)} -> #N/A | C15: {=XLOOKUP($E15,'Player Database'!$B$2:$B758,'Player Database'!$F$2:$F758)} -> #N/A | D15: =IFERROR(__xludf.DUMMYFUNCTION("""COMPUTED_VALUE"""),1.0) -> 1 | F15: {=XLOOKUP($E15,'Player Database'!$B$2:$B758,'Player Database'!$K$2:$K758)} -> #N/A | G15: {=XLOOKUP($E15,'Player Database'!$B$2:$B758,'Player Database'!$H$2:$H758)} -> #N/A | H15: {=XLOOKUP($E15,'Player Database'!$B$2:$B758,'Player Database'!$O$2:$O758)} -> #N/A | I15: {=XLOOKUP($E15,'Player Database'!$B$2:$B758,'Player Database'!$P$2:$P758)} -> #N/A | J15: {=XLOOKUP($E15,'Player Database'!$B$2:$B758,'Player Database'!$U$2:$U758)} -> #N/A | K15: =VLOOKUP(E15, 'Player Database'!B:AE, 30, FALSE) -> #N/A | L15: {=XLOOKUP($E15,'Player Database'!$B$2:$B758,'Player Database'!$W$2:$W758)} -> #N/A | M15: =CONCATENATE(O15," - ",P15) -> 0 - 0 | N15: {=IF(XLOOKUP($E15,'Player Database'!$B$2:$B758,'Player Database'!$AA$2:$AA758)="",XLOOKUP($E15,'Player Database'!$B$2:$B758,'Player Database'!$G$2:$G758),XLOOKUP($E15,'Player Database'!$B$2:$B758,'Player Database'!$AA$2:$AA758))} -> #N/A | O15: =COUNTIFs(Matches!$B:$B,E15,Matches!$A:$A,">"&Q15,Matches!$A:$A,"<"&R15) -> 0 | P15: =COUNTIFs(Matches!$C:$C,E15,Matches!$A:$A,">"&Q15,Matches!$A:$A,"<"&R15) -> 0 | Q15: =VLOOKUP($C$2,Quotas!$A$7:$E$14,2,FALSE) -> 46213.708 | R15: =VLOOKUP($C$2,Quotas!$A$7:$E$14,3,FALSE) -> 46220.708
A16: {=XLOOKUP($E16,'Player Database'!$B$2:$B758,'Player Database'!$C$2:$C758)} -> #N/A | B16: {=XLOOKUP($E16,'Player Database'!$B$2:$B758,'Player Database'!$E$2:$E758)} -> #N/A | C16: {=XLOOKUP($E16,'Player Database'!$B$2:$B758,'Player Database'!$F$2:$F758)} -> #N/A | D16: =IFERROR(__xludf.DUMMYFUNCTION("""COMPUTED_VALUE"""),1.0) -> 1 | F16: {=XLOOKUP($E16,'Player Database'!$B$2:$B758,'Player Database'!$K$2:$K758)} -> #N/A | G16: {=XLOOKUP($E16,'Player Database'!$B$2:$B758,'Player Database'!$H$2:$H758)} -> #N/A | H16: {=XLOOKUP($E16,'Player Database'!$B$2:$B758,'Player Database'!$O$2:$O758)} -> #N/A | I16: {=XLOOKUP($E16,'Player Database'!$B$2:$B758,'Player Database'!$P$2:$P758)} -> #N/A | J16: {=XLOOKUP($E16,'Player Database'!$B$2:$B758,'Player Database'!$U$2:$U758)} -> #N/A | K16: =VLOOKUP(E16, 'Player Database'!B:AE, 30, FALSE) -> #N/A | L16: {=XLOOKUP($E16,'Player Database'!$B$2:$B758,'Player Database'!$W$2:$W758)} -> #N/A | M16: =CONCATENATE(O16," - ",P16) -> 0 - 0 | N16: {=IF(XLOOKUP($E16,'Player Database'!$B$2:$B758,'Player Database'!$AA$2:$AA758)="",XLOOKUP($E16,'Player Database'!$B$2:$B758,'Player Database'!$G$2:$G758),XLOOKUP($E16,'Player Database'!$B$2:$B758,'Player Database'!$AA$2:$AA758))} -> #N/A | O16: =COUNTIFs(Matches!$B:$B,E16,Matches!$A:$A,">"&Q16,Matches!$A:$A,"<"&R16) -> 0 | P16: =COUNTIFs(Matches!$C:$C,E16,Matches!$A:$A,">"&Q16,Matches!$A:$A,"<"&R16) -> 0 | Q16: =VLOOKUP($C$2,Quotas!$A$7:$E$14,2,FALSE) -> 46213.708 | R16: =VLOOKUP($C$2,Quotas!$A$7:$E$14,3,FALSE) -> 46220.708
A17: {=XLOOKUP($E17,'Player Database'!$B$2:$B758,'Player Database'!$C$2:$C758)} -> #N/A | B17: {=XLOOKUP($E17,'Player Database'!$B$2:$B758,'Player Database'!$E$2:$E758)} -> #N/A | C17: {=XLOOKUP($E17,'Player Database'!$B$2:$B758,'Player Database'!$F$2:$F758)} -> #N/A | D17: =IFERROR(__xludf.DUMMYFUNCTION("""COMPUTED_VALUE"""),1.0) -> 1 | F17: {=XLOOKUP($E17,'Player Database'!$B$2:$B758,'Player Database'!$K$2:$K758)} -> #N/A | G17: {=XLOOKUP($E17,'Player Database'!$B$2:$B758,'Player Database'!$H$2:$H758)} -> #N/A | H17: {=XLOOKUP($E17,'Player Database'!$B$2:$B758,'Player Database'!$O$2:$O758)} -> #N/A | I17: {=XLOOKUP($E17,'Player Database'!$B$2:$B758,'Player Database'!$P$2:$P758)} -> #N/A | J17: {=XLOOKUP($E17,'Player Database'!$B$2:$B758,'Player Database'!$U$2:$U758)} -> #N/A | K17: =VLOOKUP(E17, 'Player Database'!B:AE, 30, FALSE) -> #N/A | L17: {=XLOOKUP($E17,'Player Database'!$B$2:$B758,'Player Database'!$W$2:$W758)} -> #N/A | M17: =CONCATENATE(O17," - ",P17) -> 0 - 0 | N17: {=IF(XLOOKUP($E17,'Player Database'!$B$2:$B758,'Player Database'!$AA$2:$AA758)="",XLOOKUP($E17,'Player Database'!$B$2:$B758,'Player Database'!$G$2:$G758),XLOOKUP($E17,'Player Database'!$B$2:$B758,'Player Database'!$AA$2:$AA758))} -> #N/A | O17: =COUNTIFs(Matches!$B:$B,E17,Matches!$A:$A,">"&Q17,Matches!$A:$A,"<"&R17) -> 0 | P17: =COUNTIFs(Matches!$C:$C,E17,Matches!$A:$A,">"&Q17,Matches!$A:$A,"<"&R17) -> 0 | Q17: =VLOOKUP($C$2,Quotas!$A$7:$E$14,2,FALSE) -> 46213.708 | R17: =VLOOKUP($C$2,Quotas!$A$7:$E$14,3,FALSE) -> 46220.708
A18: {=XLOOKUP($E18,'Player Database'!$B$2:$B758,'Player Database'!$C$2:$C758)} -> #N/A | B18: {=XLOOKUP($E18,'Player Database'!$B$2:$B758,'Player Database'!$E$2:$E758)} -> #N/A | C18: {=XLOOKUP($E18,'Player Database'!$B$2:$B758,'Player Database'!$F$2:$F758)} -> #N/A | D18: =IFERROR(__xludf.DUMMYFUNCTION("""COMPUTED_VALUE"""),1.0) -> 1 | F18: {=XLOOKUP($E18,'Player Database'!$B$2:$B758,'Player Database'!$K$2:$K758)} -> #N/A | G18: {=XLOOKUP($E18,'Player Database'!$B$2:$B758,'Player Database'!$H$2:$H758)} -> #N/A | H18: {=XLOOKUP($E18,'Player Database'!$B$2:$B758,'Player Database'!$O$2:$O758)} -> #N/A | I18: {=XLOOKUP($E18,'Player Database'!$B$2:$B758,'Player Database'!$P$2:$P758)} -> #N/A | J18: {=XLOOKUP($E18,'Player Database'!$B$2:$B758,'Player Database'!$U$2:$U758)} -> #N/A | K18: =VLOOKUP(E18, 'Player Database'!B:AE, 30, FALSE) -> #N/A | L18: {=XLOOKUP($E18,'Player Database'!$B$2:$B758,'Player Database'!$W$2:$W758)} -> #N/A | M18: =CONCATENATE(O18," - ",P18) -> 0 - 0 | N18: {=IF(XLOOKUP($E18,'Player Database'!$B$2:$B758,'Player Database'!$AA$2:$AA758)="",XLOOKUP($E18,'Player Database'!$B$2:$B758,'Player Database'!$G$2:$G758),XLOOKUP($E18,'Player Database'!$B$2:$B758,'Player Database'!$AA$2:$AA758))} -> #N/A | O18: =COUNTIFs(Matches!$B:$B,E18,Matches!$A:$A,">"&Q18,Matches!$A:$A,"<"&R18) -> 0 | P18: =COUNTIFs(Matches!$C:$C,E18,Matches!$A:$A,">"&Q18,Matches!$A:$A,"<"&R18) -> 0 | Q18: =VLOOKUP($C$2,Quotas!$A$7:$E$14,2,FALSE) -> 46213.708 | R18: =VLOOKUP($C$2,Quotas!$A$7:$E$14,3,FALSE) -> 46220.708
A19: {=XLOOKUP($E19,'Player Database'!$B$2:$B758,'Player Database'!$C$2:$C758)} -> #N/A | B19: {=XLOOKUP($E19,'Player Database'!$B$2:$B758,'Player Database'!$E$2:$E758)} -> #N/A | C19: {=XLOOKUP($E19,'Player Database'!$B$2:$B758,'Player Database'!$F$2:$F758)} -> #N/A | D19: =IFERROR(__xludf.DUMMYFUNCTION("""COMPUTED_VALUE"""),1.0) -> 1 | F19: {=XLOOKUP($E19,'Player Database'!$B$2:$B758,'Player Database'!$K$2:$K758)} -> #N/A | G19: {=XLOOKUP($E19,'Player Database'!$B$2:$B758,'Player Database'!$H$2:$H758)} -> #N/A | H19: {=XLOOKUP($E19,'Player Database'!$B$2:$B758,'Player Database'!$O$2:$O758)} -> #N/A | I19: {=XLOOKUP($E19,'Player Database'!$B$2:$B758,'Player Database'!$P$2:$P758)} -> #N/A | J19: {=XLOOKUP($E19,'Player Database'!$B$2:$B758,'Player Database'!$U$2:$U758)} -> #N/A | K19: =VLOOKUP(E19, 'Player Database'!B:AE, 30, FALSE) -> #N/A | L19: {=XLOOKUP($E19,'Player Database'!$B$2:$B758,'Player Database'!$W$2:$W758)} -> #N/A | M19: =CONCATENATE(O19," - ",P19) -> 0 - 0 | N19: {=IF(XLOOKUP($E19,'Player Database'!$B$2:$B758,'Player Database'!$AA$2:$AA758)="",XLOOKUP($E19,'Player Database'!$B$2:$B758,'Player Database'!$G$2:$G758),XLOOKUP($E19,'Player Database'!$B$2:$B758,'Player Database'!$AA$2:$AA758))} -> #N/A | O19: =COUNTIFs(Matches!$B:$B,E19,Matches!$A:$A,">"&Q19,Matches!$A:$A,"<"&R19) -> 0 | P19: =COUNTIFs(Matches!$C:$C,E19,Matches!$A:$A,">"&Q19,Matches!$A:$A,"<"&R19) -> 0 | Q19: =VLOOKUP($C$2,Quotas!$A$7:$E$14,2,FALSE) -> 46213.708 | R19: =VLOOKUP($C$2,Quotas!$A$7:$E$14,3,FALSE) -> 46220.708
A20: {=XLOOKUP($E20,'Player Database'!$B$2:$B758,'Player Database'!$C$2:$C758)} -> #N/A | B20: {=XLOOKUP($E20,'Player Database'!$B$2:$B758,'Player Database'!$E$2:$E758)} -> #N/A | C20: {=XLOOKUP($E20,'Player Database'!$B$2:$B758,'Player Database'!$F$2:$F758)} -> #N/A | D20: =IFERROR(__xludf.DUMMYFUNCTION("""COMPUTED_VALUE"""),1.0) -> 1 | F20: {=XLOOKUP($E20,'Player Database'!$B$2:$B758,'Player Database'!$K$2:$K758)} -> #N/A | G20: {=XLOOKUP($E20,'Player Database'!$B$2:$B758,'Player Database'!$H$2:$H758)} -> #N/A | H20: {=XLOOKUP($E20,'Player Database'!$B$2:$B758,'Player Database'!$O$2:$O758)} -> #N/A | I20: {=XLOOKUP($E20,'Player Database'!$B$2:$B758,'Player Database'!$P$2:$P758)} -> #N/A | J20: {=XLOOKUP($E20,'Player Database'!$B$2:$B758,'Player Database'!$U$2:$U758)} -> #N/A | K20: =VLOOKUP(E20, 'Player Database'!B:AE, 30, FALSE) -> #N/A | L20: {=XLOOKUP($E20,'Player Database'!$B$2:$B758,'Player Database'!$W$2:$W758)} -> #N/A | M20: =CONCATENATE(O20," - ",P20) -> 0 - 0 | N20: {=IF(XLOOKUP($E20,'Player Database'!$B$2:$B758,'Player Database'!$AA$2:$AA758)="",XLOOKUP($E20,'Player Database'!$B$2:$B758,'Player Database'!$G$2:$G758),XLOOKUP($E20,'Player Database'!$B$2:$B758,'Player Database'!$AA$2:$AA758))} -> #N/A | O20: =COUNTIFs(Matches!$B:$B,E20,Matches!$A:$A,">"&Q20,Matches!$A:$A,"<"&R20) -> 0 | P20: =COUNTIFs(Matches!$C:$C,E20,Matches!$A:$A,">"&Q20,Matches!$A:$A,"<"&R20) -> 0 | Q20: =VLOOKUP($C$2,Quotas!$A$7:$E$14,2,FALSE) -> 46213.708 | R20: =VLOOKUP($C$2,Quotas!$A$7:$E$14,3,FALSE) -> 46220.708
A21: {=XLOOKUP($E21,'Player Database'!$B$2:$B758,'Player Database'!$C$2:$C758)} -> #N/A | B21: {=XLOOKUP($E21,'Player Database'!$B$2:$B758,'Player Database'!$E$2:$E758)} -> #N/A | C21: {=XLOOKUP($E21,'Player Database'!$B$2:$B758,'Player Database'!$F$2:$F758)} -> #N/A | D21: =IFERROR(__xludf.DUMMYFUNCTION("""COMPUTED_VALUE"""),1.0) -> 1 | F21: {=XLOOKUP($E21,'Player Database'!$B$2:$B758,'Player Database'!$K$2:$K758)} -> #N/A | G21: {=XLOOKUP($E21,'Player Database'!$B$2:$B758,'Player Database'!$H$2:$H758)} -> #N/A | H21: {=XLOOKUP($E21,'Player Database'!$B$2:$B758,'Player Database'!$O$2:$O758)} -> #N/A | I21: {=XLOOKUP($E21,'Player Database'!$B$2:$B758,'Player Database'!$P$2:$P758)} -> #N/A | J21: {=XLOOKUP($E21,'Player Database'!$B$2:$B758,'Player Database'!$U$2:$U758)} -> #N/A | K21: =VLOOKUP(E21, 'Player Database'!B:AE, 30, FALSE) -> #N/A | L21: {=XLOOKUP($E21,'Player Database'!$B$2:$B758,'Player Database'!$W$2:$W758)} -> #N/A | M21: =CONCATENATE(O21," - ",P21) -> 0 - 0 | N21: {=IF(XLOOKUP($E21,'Player Database'!$B$2:$B758,'Player Database'!$AA$2:$AA758)="",XLOOKUP($E21,'Player Database'!$B$2:$B758,'Player Database'!$G$2:$G758),XLOOKUP($E21,'Player Database'!$B$2:$B758,'Player Database'!$AA$2:$AA758))} -> #N/A | O21: =COUNTIFs(Matches!$B:$B,E21,Matches!$A:$A,">"&Q21,Matches!$A:$A,"<"&R21) -> 0 | P21: =COUNTIFs(Matches!$C:$C,E21,Matches!$A:$A,">"&Q21,Matches!$A:$A,"<"&R21) -> 0 | Q21: =VLOOKUP($C$2,Quotas!$A$7:$E$14,2,FALSE) -> 46213.708 | R21: =VLOOKUP($C$2,Quotas!$A$7:$E$14,3,FALSE) -> 46220.708
A22: {=XLOOKUP($E22,'Player Database'!$B$2:$B758,'Player Database'!$C$2:$C758)} -> #N/A | B22: {=XLOOKUP($E22,'Player Database'!$B$2:$B758,'Player Database'!$E$2:$E758)} -> #N/A | C22: {=XLOOKUP($E22,'Player Database'!$B$2:$B758,'Player Database'!$F$2:$F758)} -> #N/A | D22: =IFERROR(__xludf.DUMMYFUNCTION("""COMPUTED_VALUE"""),1.0) -> 1 | F22: {=XLOOKUP($E22,'Player Database'!$B$2:$B758,'Player Database'!$K$2:$K758)} -> #N/A | G22: {=XLOOKUP($E22,'Player Database'!$B$2:$B758,'Player Database'!$H$2:$H758)} -> #N/A | H22: {=XLOOKUP($E22,'Player Database'!$B$2:$B758,'Player Database'!$O$2:$O758)} -> #N/A | I22: {=XLOOKUP($E22,'Player Database'!$B$2:$B758,'Player Database'!$P$2:$P758)} -> #N/A | J22: {=XLOOKUP($E22,'Player Database'!$B$2:$B758,'Player Database'!$U$2:$U758)} -> #N/A | K22: =VLOOKUP(E22, 'Player Database'!B:AE, 30, FALSE) -> #N/A | L22: {=XLOOKUP($E22,'Player Database'!$B$2:$B758,'Player Database'!$W$2:$W758)} -> #N/A | M22: =CONCATENATE(O22," - ",P22) -> 0 - 0 | N22: {=IF(XLOOKUP($E22,'Player Database'!$B$2:$B758,'Player Database'!$AA$2:$AA758)="",XLOOKUP($E22,'Player Database'!$B$2:$B758,'Player Database'!$G$2:$G758),XLOOKUP($E22,'Player Database'!$B$2:$B758,'Player Database'!$AA$2:$AA758))} -> #N/A | O22: =COUNTIFs(Matches!$B:$B,E22,Matches!$A:$A,">"&Q22,Matches!$A:$A,"<"&R22) -> 0 | P22: =COUNTIFs(Matches!$C:$C,E22,Matches!$A:$A,">"&Q22,Matches!$A:$A,"<"&R22) -> 0 | Q22: =VLOOKUP($C$2,Quotas!$A$7:$E$14,2,FALSE) -> 46213.708 | R22: =VLOOKUP($C$2,Quotas!$A$7:$E$14,3,FALSE) -> 46220.708
A23: {=XLOOKUP($E23,'Player Database'!$B$2:$B758,'Player Database'!$C$2:$C758)} -> #N/A | B23: {=XLOOKUP($E23,'Player Database'!$B$2:$B758,'Player Database'!$E$2:$E758)} -> #N/A | C23: {=XLOOKUP($E23,'Player Database'!$B$2:$B758,'Player Database'!$F$2:$F758)} -> #N/A | D23: =IFERROR(__xludf.DUMMYFUNCTION("""COMPUTED_VALUE"""),1.0) -> 1 | F23: {=XLOOKUP($E23,'Player Database'!$B$2:$B758,'Player Database'!$K$2:$K758)} -> #N/A | G23: {=XLOOKUP($E23,'Player Database'!$B$2:$B758,'Player Database'!$H$2:$H758)} -> #N/A | H23: {=XLOOKUP($E23,'Player Database'!$B$2:$B758,'Player Database'!$O$2:$O758)} -> #N/A | I23: {=XLOOKUP($E23,'Player Database'!$B$2:$B758,'Player Database'!$P$2:$P758)} -> #N/A | J23: {=XLOOKUP($E23,'Player Database'!$B$2:$B758,'Player Database'!$U$2:$U758)} -> #N/A | K23: =VLOOKUP(E23, 'Player Database'!B:AE, 30, FALSE) -> #N/A | L23: {=XLOOKUP($E23,'Player Database'!$B$2:$B758,'Player Database'!$W$2:$W758)} -> #N/A | M23: =CONCATENATE(O23," - ",P23) -> 0 - 0 | N23: {=IF(XLOOKUP($E23,'Player Database'!$B$2:$B758,'Player Database'!$AA$2:$AA758)="",XLOOKUP($E23,'Player Database'!$B$2:$B758,'Player Database'!$G$2:$G758),XLOOKUP($E23,'Player Database'!$B$2:$B758,'Player Database'!$AA$2:$AA758))} -> #N/A | O23: =COUNTIFs(Matches!$B:$B,E23,Matches!$A:$A,">"&Q23,Matches!$A:$A,"<"&R23) -> 0 | P23: =COUNTIFs(Matches!$C:$C,E23,Matches!$A:$A,">"&Q23,Matches!$A:$A,"<"&R23) -> 0 | Q23: =VLOOKUP($C$2,Quotas!$A$7:$E$14,2,FALSE) -> 46213.708 | R23: =VLOOKUP($C$2,Quotas!$A$7:$E$14,3,FALSE) -> 46220.708
A24: {=XLOOKUP($E24,'Player Database'!$B$2:$B758,'Player Database'!$C$2:$C758)} -> #N/A | B24: {=XLOOKUP($E24,'Player Database'!$B$2:$B758,'Player Database'!$E$2:$E758)} -> #N/A | C24: {=XLOOKUP($E24,'Player Database'!$B$2:$B758,'Player Database'!$F$2:$F758)} -> #N/A | D24: =IFERROR(__xludf.DUMMYFUNCTION("""COMPUTED_VALUE"""),1.0) -> 1 | F24: {=XLOOKUP($E24,'Player Database'!$B$2:$B758,'Player Database'!$K$2:$K758)} -> #N/A | G24: {=XLOOKUP($E24,'Player Database'!$B$2:$B758,'Player Database'!$H$2:$H758)} -> #N/A | H24: {=XLOOKUP($E24,'Player Database'!$B$2:$B758,'Player Database'!$O$2:$O758)} -> #N/A | I24: {=XLOOKUP($E24,'Player Database'!$B$2:$B758,'Player Database'!$P$2:$P758)} -> #N/A | J24: {=XLOOKUP($E24,'Player Database'!$B$2:$B758,'Player Database'!$U$2:$U758)} -> #N/A | K24: =VLOOKUP(E24, 'Player Database'!B:AE, 30, FALSE) -> #N/A | L24: {=XLOOKUP($E24,'Player Database'!$B$2:$B758,'Player Database'!$W$2:$W758)} -> #N/A | M24: =CONCATENATE(O24," - ",P24) -> 0 - 0 | N24: {=IF(XLOOKUP($E24,'Player Database'!$B$2:$B758,'Player Database'!$AA$2:$AA758)="",XLOOKUP($E24,'Player Database'!$B$2:$B758,'Player Database'!$G$2:$G758),XLOOKUP($E24,'Player Database'!$B$2:$B758,'Player Database'!$AA$2:$AA758))} -> #N/A | O24: =COUNTIFs(Matches!$B:$B,E24,Matches!$A:$A,">"&Q24,Matches!$A:$A,"<"&R24) -> 0 | P24: =COUNTIFs(Matches!$C:$C,E24,Matches!$A:$A,">"&Q24,Matches!$A:$A,"<"&R24) -> 0 | Q24: =VLOOKUP($C$2,Quotas!$A$7:$E$14,2,FALSE) -> 46213.708 | R24: =VLOOKUP($C$2,Quotas!$A$7:$E$14,3,FALSE) -> 46220.708
A25: {=XLOOKUP($E25,'Player Database'!$B$2:$B758,'Player Database'!$C$2:$C758)} -> #N/A | B25: {=XLOOKUP($E25,'Player Database'!$B$2:$B758,'Player Database'!$E$2:$E758)} -> #N/A | C25: {=XLOOKUP($E25,'Player Database'!$B$2:$B758,'Player Database'!$F$2:$F758)} -> #N/A | D25: =IFERROR(__xludf.DUMMYFUNCTION("""COMPUTED_VALUE"""),1.0) -> 1 | F25: {=XLOOKUP($E25,'Player Database'!$B$2:$B758,'Player Database'!$K$2:$K758)} -> #N/A | G25: {=XLOOKUP($E25,'Player Database'!$B$2:$B758,'Player Database'!$H$2:$H758)} -> #N/A | H25: {=XLOOKUP($E25,'Player Database'!$B$2:$B758,'Player Database'!$O$2:$O758)} -> #N/A | I25: {=XLOOKUP($E25,'Player Database'!$B$2:$B758,'Player Database'!$P$2:$P758)} -> #N/A | J25: {=XLOOKUP($E25,'Player Database'!$B$2:$B758,'Player Database'!$U$2:$U758)} -> #N/A | K25: =VLOOKUP(E25, 'Player Database'!B:AE, 30, FALSE) -> #N/A | L25: {=XLOOKUP($E25,'Player Database'!$B$2:$B758,'Player Database'!$W$2:$W758)} -> #N/A | M25: =CONCATENATE(O25," - ",P25) -> 0 - 0 | N25: {=IF(XLOOKUP($E25,'Player Database'!$B$2:$B758,'Player Database'!$AA$2:$AA758)="",XLOOKUP($E25,'Player Database'!$B$2:$B758,'Player Database'!$G$2:$G758),XLOOKUP($E25,'Player Database'!$B$2:$B758,'Player Database'!$AA$2:$AA758))} -> #N/A | O25: =COUNTIFs(Matches!$B:$B,E25,Matches!$A:$A,">"&Q25,Matches!$A:$A,"<"&R25) -> 0 | P25: =COUNTIFs(Matches!$C:$C,E25,Matches!$A:$A,">"&Q25,Matches!$A:$A,"<"&R25) -> 0 | Q25: =VLOOKUP($C$2,Quotas!$A$7:$E$14,2,FALSE) -> 46213.708 | R25: =VLOOKUP($C$2,Quotas!$A$7:$E$14,3,FALSE) -> 46220.708
A26: {=XLOOKUP($E26,'Player Database'!$B$2:$B758,'Player Database'!$C$2:$C758)} -> #N/A | B26: {=XLOOKUP($E26,'Player Database'!$B$2:$B758,'Player Database'!$E$2:$E758)} -> #N/A | C26: {=XLOOKUP($E26,'Player Database'!$B$2:$B758,'Player Database'!$F$2:$F758)} -> #N/A | D26: =IFERROR(__xludf.DUMMYFUNCTION("""COMPUTED_VALUE"""),1.0) -> 1 | F26: {=XLOOKUP($E26,'Player Database'!$B$2:$B758,'Player Database'!$K$2:$K758)} -> #N/A | G26: {=XLOOKUP($E26,'Player Database'!$B$2:$B758,'Player Database'!$H$2:$H758)} -> #N/A | H26: {=XLOOKUP($E26,'Player Database'!$B$2:$B758,'Player Database'!$O$2:$O758)} -> #N/A | I26: {=XLOOKUP($E26,'Player Database'!$B$2:$B758,'Player Database'!$P$2:$P758)} -> #N/A | J26: {=XLOOKUP($E26,'Player Database'!$B$2:$B758,'Player Database'!$U$2:$U758)} -> #N/A | K26: =VLOOKUP(E26, 'Player Database'!B:AE, 30, FALSE) -> #N/A | L26: {=XLOOKUP($E26,'Player Database'!$B$2:$B758,'Player Database'!$W$2:$W758)} -> #N/A | M26: =CONCATENATE(O26," - ",P26) -> 0 - 0 | N26: {=IF(XLOOKUP($E26,'Player Database'!$B$2:$B758,'Player Database'!$AA$2:$AA758)="",XLOOKUP($E26,'Player Database'!$B$2:$B758,'Player Database'!$G$2:$G758),XLOOKUP($E26,'Player Database'!$B$2:$B758,'Player Database'!$AA$2:$AA758))} -> #N/A | O26: =COUNTIFs(Matches!$B:$B,E26,Matches!$A:$A,">"&Q26,Matches!$A:$A,"<"&R26) -> 0 | P26: =COUNTIFs(Matches!$C:$C,E26,Matches!$A:$A,">"&Q26,Matches!$A:$A,"<"&R26) -> 0 | Q26: =VLOOKUP($C$2,Quotas!$A$7:$E$14,2,FALSE) -> 46213.708 | R26: =VLOOKUP($C$2,Quotas!$A$7:$E$14,3,FALSE) -> 46220.708
A27: {=XLOOKUP($E27,'Player Database'!$B$2:$B758,'Player Database'!$C$2:$C758)} -> #N/A | B27: {=XLOOKUP($E27,'Player Database'!$B$2:$B758,'Player Database'!$E$2:$E758)} -> #N/A | C27: {=XLOOKUP($E27,'Player Database'!$B$2:$B758,'Player Database'!$F$2:$F758)} -> #N/A | D27: =IFERROR(__xludf.DUMMYFUNCTION("""COMPUTED_VALUE"""),1.0) -> 1 | F27: {=XLOOKUP($E27,'Player Database'!$B$2:$B758,'Player Database'!$K$2:$K758)} -> #N/A | G27: {=XLOOKUP($E27,'Player Database'!$B$2:$B758,'Player Database'!$H$2:$H758)} -> #N/A | H27: {=XLOOKUP($E27,'Player Database'!$B$2:$B758,'Player Database'!$O$2:$O758)} -> #N/A | I27: {=XLOOKUP($E27,'Player Database'!$B$2:$B758,'Player Database'!$P$2:$P758)} -> #N/A | J27: {=XLOOKUP($E27,'Player Database'!$B$2:$B758,'Player Database'!$U$2:$U758)} -> #N/A | K27: =VLOOKUP(E27, 'Player Database'!B:AE, 30, FALSE) -> #N/A | L27: {=XLOOKUP($E27,'Player Database'!$B$2:$B758,'Player Database'!$W$2:$W758)} -> #N/A | M27: =CONCATENATE(O27," - ",P27) -> 0 - 0 | N27: {=IF(XLOOKUP($E27,'Player Database'!$B$2:$B758,'Player Database'!$AA$2:$AA758)="",XLOOKUP($E27,'Player Database'!$B$2:$B758,'Player Database'!$G$2:$G758),XLOOKUP($E27,'Player Database'!$B$2:$B758,'Player Database'!$AA$2:$AA758))} -> #N/A | O27: =COUNTIFs(Matches!$B:$B,E27,Matches!$A:$A,">"&Q27,Matches!$A:$A,"<"&R27) -> 0 | P27: =COUNTIFs(Matches!$C:$C,E27,Matches!$A:$A,">"&Q27,Matches!$A:$A,"<"&R27) -> 0 | Q27: =VLOOKUP($C$2,Quotas!$A$7:$E$14,2,FALSE) -> 46213.708 | R27: =VLOOKUP($C$2,Quotas!$A$7:$E$14,3,FALSE) -> 46220.708
A28: {=XLOOKUP($E28,'Player Database'!$B$2:$B758,'Player Database'!$C$2:$C758)} -> #N/A | B28: {=XLOOKUP($E28,'Player Database'!$B$2:$B758,'Player Database'!$E$2:$E758)} -> #N/A | C28: {=XLOOKUP($E28,'Player Database'!$B$2:$B758,'Player Database'!$F$2:$F758)} -> #N/A | D28: =IFERROR(__xludf.DUMMYFUNCTION("""COMPUTED_VALUE"""),1.0) -> 1 | F28: {=XLOOKUP($E28,'Player Database'!$B$2:$B758,'Player Database'!$K$2:$K758)} -> #N/A | G28: {=XLOOKUP($E28,'Player Database'!$B$2:$B758,'Player Database'!$H$2:$H758)} -> #N/A | H28: {=XLOOKUP($E28,'Player Database'!$B$2:$B758,'Player Database'!$O$2:$O758)} -> #N/A | I28: {=XLOOKUP($E28,'Player Database'!$B$2:$B758,'Player Database'!$P$2:$P758)} -> #N/A | J28: {=XLOOKUP($E28,'Player Database'!$B$2:$B758,'Player Database'!$U$2:$U758)} -> #N/A | K28: =VLOOKUP(E28, 'Player Database'!B:AE, 30, FALSE) -> #N/A | L28: {=XLOOKUP($E28,'Player Database'!$B$2:$B758,'Player Database'!$W$2:$W758)} -> #N/A | M28: =CONCATENATE(O28," - ",P28) -> 0 - 0 | N28: {=IF(XLOOKUP($E28,'Player Database'!$B$2:$B758,'Player Database'!$AA$2:$AA758)="",XLOOKUP($E28,'Player Database'!$B$2:$B758,'Player Database'!$G$2:$G758),XLOOKUP($E28,'Player Database'!$B$2:$B758,'Player Database'!$AA$2:$AA758))} -> #N/A | O28: =COUNTIFs(Matches!$B:$B,E28,Matches!$A:$A,">"&Q28,Matches!$A:$A,"<"&R28) -> 0 | P28: =COUNTIFs(Matches!$C:$C,E28,Matches!$A:$A,">"&Q28,Matches!$A:$A,"<"&R28) -> 0 | Q28: =VLOOKUP($C$2,Quotas!$A$7:$E$14,2,FALSE) -> 46213.708 | R28: =VLOOKUP($C$2,Quotas!$A$7:$E$14,3,FALSE) -> 46220.708
A29: {=XLOOKUP($E29,'Player Database'!$B$2:$B758,'Player Database'!$C$2:$C758)} -> #N/A | B29: {=XLOOKUP($E29,'Player Database'!$B$2:$B758,'Player Database'!$E$2:$E758)} -> #N/A | C29: {=XLOOKUP($E29,'Player Database'!$B$2:$B758,'Player Database'!$F$2:$F758)} -> #N/A | D29: =IFERROR(__xludf.DUMMYFUNCTION("""COMPUTED_VALUE"""),1.0) -> 1 | F29: {=XLOOKUP($E29,'Player Database'!$B$2:$B758,'Player Database'!$K$2:$K758)} -> #N/A | G29: {=XLOOKUP($E29,'Player Database'!$B$2:$B758,'Player Database'!$H$2:$H758)} -> #N/A | H29: {=XLOOKUP($E29,'Player Database'!$B$2:$B758,'Player Database'!$O$2:$O758)} -> #N/A | I29: {=XLOOKUP($E29,'Player Database'!$B$2:$B758,'Player Database'!$P$2:$P758)} -> #N/A | J29: {=XLOOKUP($E29,'Player Database'!$B$2:$B758,'Player Database'!$U$2:$U758)} -> #N/A | K29: =VLOOKUP(E29, 'Player Database'!B:AE, 30, FALSE) -> #N/A | L29: {=XLOOKUP($E29,'Player Database'!$B$2:$B758,'Player Database'!$W$2:$W758)} -> #N/A | M29: =CONCATENATE(O29," - ",P29) -> 0 - 0 | N29: {=IF(XLOOKUP($E29,'Player Database'!$B$2:$B758,'Player Database'!$AA$2:$AA758)="",XLOOKUP($E29,'Player Database'!$B$2:$B758,'Player Database'!$G$2:$G758),XLOOKUP($E29,'Player Database'!$B$2:$B758,'Player Database'!$AA$2:$AA758))} -> #N/A | O29: =COUNTIFs(Matches!$B:$B,E29,Matches!$A:$A,">"&Q29,Matches!$A:$A,"<"&R29) -> 0 | P29: =COUNTIFs(Matches!$C:$C,E29,Matches!$A:$A,">"&Q29,Matches!$A:$A,"<"&R29) -> 0 | Q29: =VLOOKUP($C$2,Quotas!$A$7:$E$14,2,FALSE) -> 46213.708 | R29: =VLOOKUP($C$2,Quotas!$A$7:$E$14,3,FALSE) -> 46220.708
A30: {=XLOOKUP($E30,'Player Database'!$B$2:$B758,'Player Database'!$C$2:$C758)} -> #N/A | B30: {=XLOOKUP($E30,'Player Database'!$B$2:$B758,'Player Database'!$E$2:$E758)} -> #N/A | C30: {=XLOOKUP($E30,'Player Database'!$B$2:$B758,'Player Database'!$F$2:$F758)} -> #N/A | D30: =IFERROR(__xludf.DUMMYFUNCTION("""COMPUTED_VALUE"""),1.0) -> 1 | F30: {=XLOOKUP($E30,'Player Database'!$B$2:$B758,'Player Database'!$K$2:$K758)} -> #N/A | G30: {=XLOOKUP($E30,'Player Database'!$B$2:$B758,'Player Database'!$H$2:$H758)} -> #N/A | H30: {=XLOOKUP($E30,'Player Database'!$B$2:$B758,'Player Database'!$O$2:$O758)} -> #N/A | I30: {=XLOOKUP($E30,'Player Database'!$B$2:$B758,'Player Database'!$P$2:$P758)} -> #N/A | J30: {=XLOOKUP($E30,'Player Database'!$B$2:$B758,'Player Database'!$U$2:$U758)} -> #N/A | K30: =VLOOKUP(E30, 'Player Database'!B:AE, 30, FALSE) -> #N/A | L30: {=XLOOKUP($E30,'Player Database'!$B$2:$B758,'Player Database'!$W$2:$W758)} -> #N/A | M30: =CONCATENATE(O30," - ",P30) -> 0 - 0 | N30: {=IF(XLOOKUP($E30,'Player Database'!$B$2:$B758,'Player Database'!$AA$2:$AA758)="",XLOOKUP($E30,'Player Database'!$B$2:$B758,'Player Database'!$G$2:$G758),XLOOKUP($E30,'Player Database'!$B$2:$B758,'Player Database'!$AA$2:$AA758))} -> #N/A | O30: =COUNTIFs(Matches!$B:$B,E30,Matches!$A:$A,">"&Q30,Matches!$A:$A,"<"&R30) -> 0 | P30: =COUNTIFs(Matches!$C:$C,E30,Matches!$A:$A,">"&Q30,Matches!$A:$A,"<"&R30) -> 0 | Q30: =VLOOKUP($C$2,Quotas!$A$7:$E$14,2,FALSE) -> 46213.708 | R30: =VLOOKUP($C$2,Quotas!$A$7:$E$14,3,FALSE) -> 46220.708
A31: {=XLOOKUP($E31,'Player Database'!$B$2:$B758,'Player Database'!$C$2:$C758)} -> #N/A | B31: {=XLOOKUP($E31,'Player Database'!$B$2:$B758,'Player Database'!$E$2:$E758)} -> #N/A | C31: {=XLOOKUP($E31,'Player Database'!$B$2:$B758,'Player Database'!$F$2:$F758)} -> #N/A | D31: =IFERROR(__xludf.DUMMYFUNCTION("""COMPUTED_VALUE"""),1.0) -> 1 | F31: {=XLOOKUP($E31,'Player Database'!$B$2:$B758,'Player Database'!$K$2:$K758)} -> #N/A | G31: {=XLOOKUP($E31,'Player Database'!$B$2:$B758,'Player Database'!$H$2:$H758)} -> #N/A | H31: {=XLOOKUP($E31,'Player Database'!$B$2:$B758,'Player Database'!$O$2:$O758)} -> #N/A | I31: {=XLOOKUP($E31,'Player Database'!$B$2:$B758,'Player Database'!$P$2:$P758)} -> #N/A | J31: {=XLOOKUP($E31,'Player Database'!$B$2:$B758,'Player Database'!$U$2:$U758)} -> #N/A | K31: =VLOOKUP(E31, 'Player Database'!B:AE, 30, FALSE) -> #N/A | L31: {=XLOOKUP($E31,'Player Database'!$B$2:$B758,'Player Database'!$W$2:$W758)} -> #N/A | M31: =CONCATENATE(O31," - ",P31) -> 0 - 0 | N31: {=IF(XLOOKUP($E31,'Player Database'!$B$2:$B758,'Player Database'!$AA$2:$AA758)="",XLOOKUP($E31,'Player Database'!$B$2:$B758,'Player Database'!$G$2:$G758),XLOOKUP($E31,'Player Database'!$B$2:$B758,'Player Database'!$AA$2:$AA758))} -> #N/A | O31: =COUNTIFs(Matches!$B:$B,E31,Matches!$A:$A,">"&Q31,Matches!$A:$A,"<"&R31) -> 0 | P31: =COUNTIFs(Matches!$C:$C,E31,Matches!$A:$A,">"&Q31,Matches!$A:$A,"<"&R31) -> 0 | Q31: =VLOOKUP($C$2,Quotas!$A$7:$E$14,2,FALSE) -> 46213.708 | R31: =VLOOKUP($C$2,Quotas!$A$7:$E$14,3,FALSE) -> 46220.708
A32: {=XLOOKUP($E32,'Player Database'!$B$2:$B758,'Player Database'!$C$2:$C758)} -> #N/A | B32: {=XLOOKUP($E32,'Player Database'!$B$2:$B758,'Player Database'!$E$2:$E758)} -> #N/A | C32: {=XLOOKUP($E32,'Player Database'!$B$2:$B758,'Player Database'!$F$2:$F758)} -> #N/A | D32: =IFERROR(__xludf.DUMMYFUNCTION("""COMPUTED_VALUE"""),1.0) -> 1 | F32: {=XLOOKUP($E32,'Player Database'!$B$2:$B758,'Player Database'!$K$2:$K758)} -> #N/A | G32: {=XLOOKUP($E32,'Player Database'!$B$2:$B758,'Player Database'!$H$2:$H758)} -> #N/A | H32: {=XLOOKUP($E32,'Player Database'!$B$2:$B758,'Player Database'!$O$2:$O758)} -> #N/A | I32: {=XLOOKUP($E32,'Player Database'!$B$2:$B758,'Player Database'!$P$2:$P758)} -> #N/A | J32: {=XLOOKUP($E32,'Player Database'!$B$2:$B758,'Player Database'!$U$2:$U758)} -> #N/A | K32: =VLOOKUP(E32, 'Player Database'!B:AE, 30, FALSE) -> #N/A | L32: {=XLOOKUP($E32,'Player Database'!$B$2:$B758,'Player Database'!$W$2:$W758)} -> #N/A | M32: =CONCATENATE(O32," - ",P32) -> 0 - 0 | N32: {=IF(XLOOKUP($E32,'Player Database'!$B$2:$B758,'Player Database'!$AA$2:$AA758)="",XLOOKUP($E32,'Player Database'!$B$2:$B758,'Player Database'!$G$2:$G758),XLOOKUP($E32,'Player Database'!$B$2:$B758,'Player Database'!$AA$2:$AA758))} -> #N/A | O32: =COUNTIFs(Matches!$B:$B,E32,Matches!$A:$A,">"&Q32,Matches!$A:$A,"<"&R32) -> 0 | P32: =COUNTIFs(Matches!$C:$C,E32,Matches!$A:$A,">"&Q32,Matches!$A:$A,"<"&R32) -> 0 | Q32: =VLOOKUP($C$2,Quotas!$A$7:$E$14,2,FALSE) -> 46213.708 | R32: =VLOOKUP($C$2,Quotas!$A$7:$E$14,3,FALSE) -> 46220.708
A33: {=XLOOKUP($E33,'Player Database'!$B$2:$B758,'Player Database'!$C$2:$C758)} -> #N/A | B33: {=XLOOKUP($E33,'Player Database'!$B$2:$B758,'Player Database'!$E$2:$E758)} -> #N/A | C33: {=XLOOKUP($E33,'Player Database'!$B$2:$B758,'Player Database'!$F$2:$F758)} -> #N/A | D33: =IFERROR(__xludf.DUMMYFUNCTION("""COMPUTED_VALUE"""),1.0) -> 1 | F33: {=XLOOKUP($E33,'Player Database'!$B$2:$B758,'Player Database'!$K$2:$K758)} -> #N/A | G33: {=XLOOKUP($E33,'Player Database'!$B$2:$B758,'Player Database'!$H$2:$H758)} -> #N/A | H33: {=XLOOKUP($E33,'Player Database'!$B$2:$B758,'Player Database'!$O$2:$O758)} -> #N/A | I33: {=XLOOKUP($E33,'Player Database'!$B$2:$B758,'Player Database'!$P$2:$P758)} -> #N/A | J33: {=XLOOKUP($E33,'Player Database'!$B$2:$B758,'Player Database'!$U$2:$U758)} -> #N/A | K33: =VLOOKUP(E33, 'Player Database'!B:AE, 30, FALSE) -> #N/A | L33: {=XLOOKUP($E33,'Player Database'!$B$2:$B758,'Player Database'!$W$2:$W758)} -> #N/A | M33: =CONCATENATE(O33," - ",P33) -> 0 - 0 | N33: {=IF(XLOOKUP($E33,'Player Database'!$B$2:$B758,'Player Database'!$AA$2:$AA758)="",XLOOKUP($E33,'Player Database'!$B$2:$B758,'Player Database'!$G$2:$G758),XLOOKUP($E33,'Player Database'!$B$2:$B758,'Player Database'!$AA$2:$AA758))} -> #N/A | O33: =COUNTIFs(Matches!$B:$B,E33,Matches!$A:$A,">"&Q33,Matches!$A:$A,"<"&R33) -> 0 | P33: =COUNTIFs(Matches!$C:$C,E33,Matches!$A:$A,">"&Q33,Matches!$A:$A,"<"&R33) -> 0 | Q33: =VLOOKUP($C$2,Quotas!$A$7:$E$14,2,FALSE) -> 46213.708 | R33: =VLOOKUP($C$2,Quotas!$A$7:$E$14,3,FALSE) -> 46220.708
A34: {=XLOOKUP($E34,'Player Database'!$B$2:$B758,'Player Database'!$C$2:$C758)} -> #N/A | B34: {=XLOOKUP($E34,'Player Database'!$B$2:$B758,'Player Database'!$E$2:$E758)} -> #N/A | C34: {=XLOOKUP($E34,'Player Database'!$B$2:$B758,'Player Database'!$F$2:$F758)} -> #N/A | D34: =IFERROR(__xludf.DUMMYFUNCTION("""COMPUTED_VALUE"""),1.0) -> 1 | F34: {=XLOOKUP($E34,'Player Database'!$B$2:$B758,'Player Database'!$K$2:$K758)} -> #N/A | G34: {=XLOOKUP($E34,'Player Database'!$B$2:$B758,'Player Database'!$H$2:$H758)} -> #N/A | H34: {=XLOOKUP($E34,'Player Database'!$B$2:$B758,'Player Database'!$O$2:$O758)} -> #N/A | I34: {=XLOOKUP($E34,'Player Database'!$B$2:$B758,'Player Database'!$P$2:$P758)} -> #N/A | J34: {=XLOOKUP($E34,'Player Database'!$B$2:$B758,'Player Database'!$U$2:$U758)} -> #N/A | K34: =VLOOKUP(E34, 'Player Database'!B:AE, 30, FALSE) -> #N/A | L34: {=XLOOKUP($E34,'Player Database'!$B$2:$B758,'Player Database'!$W$2:$W758)} -> #N/A | M34: =CONCATENATE(O34," - ",P34) -> 0 - 0 | N34: {=IF(XLOOKUP($E34,'Player Database'!$B$2:$B758,'Player Database'!$AA$2:$AA758)="",XLOOKUP($E34,'Player Database'!$B$2:$B758,'Player Database'!$G$2:$G758),XLOOKUP($E34,'Player Database'!$B$2:$B758,'Player Database'!$AA$2:$AA758))} -> #N/A | O34: =COUNTIFs(Matches!$B:$B,E34,Matches!$A:$A,">"&Q34,Matches!$A:$A,"<"&R34) -> 0 | P34: =COUNTIFs(Matches!$C:$C,E34,Matches!$A:$A,">"&Q34,Matches!$A:$A,"<"&R34) -> 0 | Q34: =VLOOKUP($C$2,Quotas!$A$7:$E$14,2,FALSE) -> 46213.708 | R34: =VLOOKUP($C$2,Quotas!$A$7:$E$14,3,FALSE) -> 46220.708
A35: {=XLOOKUP($E35,'Player Database'!$B$2:$B758,'Player Database'!$C$2:$C758)} -> #N/A | B35: {=XLOOKUP($E35,'Player Database'!$B$2:$B758,'Player Database'!$E$2:$E758)} -> #N/A | C35: {=XLOOKUP($E35,'Player Database'!$B$2:$B758,'Player Database'!$F$2:$F758)} -> #N/A | D35: =IFERROR(__xludf.DUMMYFUNCTION("""COMPUTED_VALUE"""),1.0) -> 1 | F35: {=XLOOKUP($E35,'Player Database'!$B$2:$B758,'Player Database'!$K$2:$K758)} -> #N/A | G35: {=XLOOKUP($E35,'Player Database'!$B$2:$B758,'Player Database'!$H$2:$H758)} -> #N/A | H35: {=XLOOKUP($E35,'Player Database'!$B$2:$B758,'Player Database'!$O$2:$O758)} -> #N/A | I35: {=XLOOKUP($E35,'Player Database'!$B$2:$B758,'Player Database'!$P$2:$P758)} -> #N/A | J35: {=XLOOKUP($E35,'Player Database'!$B$2:$B758,'Player Database'!$U$2:$U758)} -> #N/A | K35: =VLOOKUP(E35, 'Player Database'!B:AE, 30, FALSE) -> #N/A | L35: {=XLOOKUP($E35,'Player Database'!$B$2:$B758,'Player Database'!$W$2:$W758)} -> #N/A | M35: =CONCATENATE(O35," - ",P35) -> 0 - 0 | N35: {=IF(XLOOKUP($E35,'Player Database'!$B$2:$B758,'Player Database'!$AA$2:$AA758)="",XLOOKUP($E35,'Player Database'!$B$2:$B758,'Player Database'!$G$2:$G758),XLOOKUP($E35,'Player Database'!$B$2:$B758,'Player Database'!$AA$2:$AA758))} -> #N/A | O35: =COUNTIFs(Matches!$B:$B,E35,Matches!$A:$A,">"&Q35,Matches!$A:$A,"<"&R35) -> 0 | P35: =COUNTIFs(Matches!$C:$C,E35,Matches!$A:$A,">"&Q35,Matches!$A:$A,"<"&R35) -> 0 | Q35: =VLOOKUP($C$2,Quotas!$A$7:$E$14,2,FALSE) -> 46213.708 | R35: =VLOOKUP($C$2,Quotas!$A$7:$E$14,3,FALSE) -> 46220.708
A36: {=XLOOKUP($E36,'Player Database'!$B$2:$B758,'Player Database'!$C$2:$C758)} -> #N/A | B36: {=XLOOKUP($E36,'Player Database'!$B$2:$B758,'Player Database'!$E$2:$E758)} -> #N/A | C36: {=XLOOKUP($E36,'Player Database'!$B$2:$B758,'Player Database'!$F$2:$F758)} -> #N/A | D36: =IFERROR(__xludf.DUMMYFUNCTION("""COMPUTED_VALUE"""),1.0) -> 1 | F36: {=XLOOKUP($E36,'Player Database'!$B$2:$B758,'Player Database'!$K$2:$K758)} -> #N/A | G36: {=XLOOKUP($E36,'Player Database'!$B$2:$B758,'Player Database'!$H$2:$H758)} -> #N/A | H36: {=XLOOKUP($E36,'Player Database'!$B$2:$B758,'Player Database'!$O$2:$O758)} -> #N/A | I36: {=XLOOKUP($E36,'Player Database'!$B$2:$B758,'Player Database'!$P$2:$P758)} -> #N/A | J36: {=XLOOKUP($E36,'Player Database'!$B$2:$B758,'Player Database'!$U$2:$U758)} -> #N/A | K36: =VLOOKUP(E36, 'Player Database'!B:AE, 30, FALSE) -> #N/A | L36: {=XLOOKUP($E36,'Player Database'!$B$2:$B758,'Player Database'!$W$2:$W758)} -> #N/A | M36: =CONCATENATE(O36," - ",P36) -> 0 - 0 | N36: {=IF(XLOOKUP($E36,'Player Database'!$B$2:$B758,'Player Database'!$AA$2:$AA758)="",XLOOKUP($E36,'Player Database'!$B$2:$B758,'Player Database'!$G$2:$G758),XLOOKUP($E36,'Player Database'!$B$2:$B758,'Player Database'!$AA$2:$AA758))} -> #N/A | O36: =COUNTIFs(Matches!$B:$B,E36,Matches!$A:$A,">"&Q36,Matches!$A:$A,"<"&R36) -> 0 | P36: =COUNTIFs(Matches!$C:$C,E36,Matches!$A:$A,">"&Q36,Matches!$A:$A,"<"&R36) -> 0 | Q36: =VLOOKUP($C$2,Quotas!$A$7:$E$14,2,FALSE) -> 46213.708 | R36: =VLOOKUP($C$2,Quotas!$A$7:$E$14,3,FALSE) -> 46220.708
A37: {=XLOOKUP($E37,'Player Database'!$B$2:$B758,'Player Database'!$C$2:$C758)} -> #N/A | B37: {=XLOOKUP($E37,'Player Database'!$B$2:$B758,'Player Database'!$E$2:$E758)} -> #N/A | C37: {=XLOOKUP($E37,'Player Database'!$B$2:$B758,'Player Database'!$F$2:$F758)} -> #N/A | D37: =IFERROR(__xludf.DUMMYFUNCTION("""COMPUTED_VALUE"""),1.0) -> 1 | F37: {=XLOOKUP($E37,'Player Database'!$B$2:$B758,'Player Database'!$K$2:$K758)} -> #N/A | G37: {=XLOOKUP($E37,'Player Database'!$B$2:$B758,'Player Database'!$H$2:$H758)} -> #N/A | H37: {=XLOOKUP($E37,'Player Database'!$B$2:$B758,'Player Database'!$O$2:$O758)} -> #N/A | I37: {=XLOOKUP($E37,'Player Database'!$B$2:$B758,'Player Database'!$P$2:$P758)} -> #N/A | J37: {=XLOOKUP($E37,'Player Database'!$B$2:$B758,'Player Database'!$U$2:$U758)} -> #N/A | K37: =VLOOKUP(E37, 'Player Database'!B:AE, 30, FALSE) -> #N/A | L37: {=XLOOKUP($E37,'Player Database'!$B$2:$B758,'Player Database'!$W$2:$W758)} -> #N/A | M37: =CONCATENATE(O37," - ",P37) -> 0 - 0 | N37: {=IF(XLOOKUP($E37,'Player Database'!$B$2:$B758,'Player Database'!$AA$2:$AA758)="",XLOOKUP($E37,'Player Database'!$B$2:$B758,'Player Database'!$G$2:$G758),XLOOKUP($E37,'Player Database'!$B$2:$B758,'Player Database'!$AA$2:$AA758))} -> #N/A | O37: =COUNTIFs(Matches!$B:$B,E37,Matches!$A:$A,">"&Q37,Matches!$A:$A,"<"&R37) -> 0 | P37: =COUNTIFs(Matches!$C:$C,E37,Matches!$A:$A,">"&Q37,Matches!$A:$A,"<"&R37) -> 0 | Q37: =VLOOKUP($C$2,Quotas!$A$7:$E$14,2,FALSE) -> 46213.708 | R37: =VLOOKUP($C$2,Quotas!$A$7:$E$14,3,FALSE) -> 46220.708
A38: {=XLOOKUP($E38,'Player Database'!$B$2:$B758,'Player Database'!$C$2:$C758)} -> #N/A | B38: {=XLOOKUP($E38,'Player Database'!$B$2:$B758,'Player Database'!$E$2:$E758)} -> #N/A | C38: {=XLOOKUP($E38,'Player Database'!$B$2:$B758,'Player Database'!$F$2:$F758)} -> #N/A | D38: =IFERROR(__xludf.DUMMYFUNCTION("""COMPUTED_VALUE"""),1.0) -> 1 | F38: {=XLOOKUP($E38,'Player Database'!$B$2:$B758,'Player Database'!$K$2:$K758)} -> #N/A | G38: {=XLOOKUP($E38,'Player Database'!$B$2:$B758,'Player Database'!$H$2:$H758)} -> #N/A | H38: {=XLOOKUP($E38,'Player Database'!$B$2:$B758,'Player Database'!$O$2:$O758)} -> #N/A | I38: {=XLOOKUP($E38,'Player Database'!$B$2:$B758,'Player Database'!$P$2:$P758)} -> #N/A | J38: {=XLOOKUP($E38,'Player Database'!$B$2:$B758,'Player Database'!$U$2:$U758)} -> #N/A | K38: =VLOOKUP(E38, 'Player Database'!B:AE, 30, FALSE) -> #N/A | L38: {=XLOOKUP($E38,'Player Database'!$B$2:$B758,'Player Database'!$W$2:$W758)} -> #N/A | M38: =CONCATENATE(O38," - ",P38) -> 0 - 0 | N38: {=IF(XLOOKUP($E38,'Player Database'!$B$2:$B758,'Player Database'!$AA$2:$AA758)="",XLOOKUP($E38,'Player Database'!$B$2:$B758,'Player Database'!$G$2:$G758),XLOOKUP($E38,'Player Database'!$B$2:$B758,'Player Database'!$AA$2:$AA758))} -> #N/A | O38: =COUNTIFs(Matches!$B:$B,E38,Matches!$A:$A,">"&Q38,Matches!$A:$A,"<"&R38) -> 0 | P38: =COUNTIFs(Matches!$C:$C,E38,Matches!$A:$A,">"&Q38,Matches!$A:$A,"<"&R38) -> 0 | Q38: =VLOOKUP($C$2,Quotas!$A$7:$E$14,2,FALSE) -> 46213.708 | R38: =VLOOKUP($C$2,Quotas!$A$7:$E$14,3,FALSE) -> 46220.708
A39: {=XLOOKUP($E39,'Player Database'!$B$2:$B758,'Player Database'!$C$2:$C758)} -> #N/A | B39: {=XLOOKUP($E39,'Player Database'!$B$2:$B758,'Player Database'!$E$2:$E758)} -> #N/A | C39: {=XLOOKUP($E39,'Player Database'!$B$2:$B758,'Player Database'!$F$2:$F758)} -> #N/A | D39: =IFERROR(__xludf.DUMMYFUNCTION("""COMPUTED_VALUE"""),1.0) -> 1 | F39: {=XLOOKUP($E39,'Player Database'!$B$2:$B758,'Player Database'!$K$2:$K758)} -> #N/A | G39: {=XLOOKUP($E39,'Player Database'!$B$2:$B758,'Player Database'!$H$2:$H758)} -> #N/A | H39: {=XLOOKUP($E39,'Player Database'!$B$2:$B758,'Player Database'!$O$2:$O758)} -> #N/A | I39: {=XLOOKUP($E39,'Player Database'!$B$2:$B758,'Player Database'!$P$2:$P758)} -> #N/A | J39: {=XLOOKUP($E39,'Player Database'!$B$2:$B758,'Player Database'!$U$2:$U758)} -> #N/A | K39: =VLOOKUP(E39, 'Player Database'!B:AE, 30, FALSE) -> #N/A | L39: {=XLOOKUP($E39,'Player Database'!$B$2:$B758,'Player Database'!$W$2:$W758)} -> #N/A | M39: =CONCATENATE(O39," - ",P39) -> 0 - 0 | N39: {=IF(XLOOKUP($E39,'Player Database'!$B$2:$B758,'Player Database'!$AA$2:$AA758)="",XLOOKUP($E39,'Player Database'!$B$2:$B758,'Player Database'!$G$2:$G758),XLOOKUP($E39,'Player Database'!$B$2:$B758,'Player Database'!$AA$2:$AA758))} -> #N/A | O39: =COUNTIFs(Matches!$B:$B,E39,Matches!$A:$A,">"&Q39,Matches!$A:$A,"<"&R39) -> 0 | P39: =COUNTIFs(Matches!$C:$C,E39,Matches!$A:$A,">"&Q39,Matches!$A:$A,"<"&R39) -> 0 | Q39: =VLOOKUP($C$2,Quotas!$A$7:$E$14,2,FALSE) -> 46213.708 | R39: =VLOOKUP($C$2,Quotas!$A$7:$E$14,3,FALSE) -> 46220.708
A40: {=XLOOKUP($E40,'Player Database'!$B$2:$B758,'Player Database'!$C$2:$C758)} -> #N/A | B40: {=XLOOKUP($E40,'Player Database'!$B$2:$B758,'Player Database'!$E$2:$E758)} -> #N/A | C40: {=XLOOKUP($E40,'Player Database'!$B$2:$B758,'Player Database'!$F$2:$F758)} -> #N/A | D40: =IFERROR(__xludf.DUMMYFUNCTION("""COMPUTED_VALUE"""),1.0) -> 1 | F40: {=XLOOKUP($E40,'Player Database'!$B$2:$B758,'Player Database'!$K$2:$K758)} -> #N/A | G40: {=XLOOKUP($E40,'Player Database'!$B$2:$B758,'Player Database'!$H$2:$H758)} -> #N/A | H40: {=XLOOKUP($E40,'Player Database'!$B$2:$B758,'Player Database'!$O$2:$O758)} -> #N/A | I40: {=XLOOKUP($E40,'Player Database'!$B$2:$B758,'Player Database'!$P$2:$P758)} -> #N/A | J40: {=XLOOKUP($E40,'Player Database'!$B$2:$B758,'Player Database'!$U$2:$U758)} -> #N/A | K40: =VLOOKUP(E40, 'Player Database'!B:AE, 30, FALSE) -> #N/A | L40: {=XLOOKUP($E40,'Player Database'!$B$2:$B758,'Player Database'!$W$2:$W758)} -> #N/A | M40: =CONCATENATE(O40," - ",P40) -> 0 - 0 | N40: {=IF(XLOOKUP($E40,'Player Database'!$B$2:$B758,'Player Database'!$AA$2:$AA758)="",XLOOKUP($E40,'Player Database'!$B$2:$B758,'Player Database'!$G$2:$G758),XLOOKUP($E40,'Player Database'!$B$2:$B758,'Player Database'!$AA$2:$AA758))} -> #N/A | O40: =COUNTIFs(Matches!$B:$B,E40,Matches!$A:$A,">"&Q40,Matches!$A:$A,"<"&R40) -> 0 | P40: =COUNTIFs(Matches!$C:$C,E40,Matches!$A:$A,">"&Q40,Matches!$A:$A,"<"&R40) -> 0 | Q40: =VLOOKUP($C$2,Quotas!$A$7:$E$14,2,FALSE) -> 46213.708 | R40: =VLOOKUP($C$2,Quotas!$A$7:$E$14,3,FALSE) -> 46220.708
...

Sheet Hero Standings
A1: ARENA GAUNTLET LEAGUE: Marvel Super Heroes AGENCY OF HEROES
A2: Week: | C2: =Quotas!B2 -> 3
A3: PLAYER NAME | B3: ARENA ID | C3: COUNTRY | D3: RANK | E3: Player Name & ID | F3: RECORD | G3: MATCHES PLAYED | H3: MATCHES <Min | I3: MATCHES <Max | J3: OMW% | K3: HERO SCORE | L3: MATCHES TO PLAY STATUS | M3: THIS WEEK | N3: OTHER INFO
A4: =IFERROR(__xludf.DUMMYFUNCTION("QUERY('Combined Standings'!A4:N175, ""Select A, B, C Where K > -1"")"),"#N/A") -> #N/A | D4: 1 | F4: =IFERROR(__xludf.DUMMYFUNCTION("QUERY('Combined Standings'!A4:N175, ""Select F, G, H, I, J, K, L, M, N Where K > -1"")"),"#N/A") -> #N/A
D5: =IF(A5="", "", D4+1)
D6: =IF(A6="", "", D5+1)
D7: =IF(A7="", "", D6+1)
D8: =IF(A8="", "", D7+1)
D9: =IF(A9="", "", D8+1)
D10: =IF(A10="", "", D9+1)
D11: =IF(A11="", "", D10+1)
D12: =IF(A12="", "", D11+1)
D13: =IF(A13="", "", D12+1)
D14: =IF(A14="", "", D13+1)
D15: =IF(A15="", "", D14+1)
D16: =IF(A16="", "", D15+1)
... D120: =IF(A120="", "", D119+1)
A121: ENTROPY | F121: =IFERROR(__xludf.DUMMYFUNCTION("CONCATENATE(TO_TEXT(SUM('Player Database'!$K:$K)),"" - 0"")"),"0 - 0") -> 0 - 0 | G121: =COUNTIF(Entropy!$C:$C,A121) -> 98
A122: TOTALS (incl entropy) | F122: =IFERROR(__xludf.DUMMYFUNCTION("CONCATENATE(TO_TEXT(SUM('Player Database'!$I$2:$I945)),"" - "",TO_TEXT(SUM('Player Database'!$J$2:$J945)))"),"0 - 0") -> 0 - 0 | G122: =SUM(G4:G121) -> 98 | H122: =SUMif(H4:H120,">0") -> 0 | I122: =SUMif(I4:I120,">0") -> 0
A123: TOTALS (w/o entropy) | F123: =IFERROR(__xludf.DUMMYFUNCTION("CONCATENATE(TO_TEXT(SUM('Player Database'!$I$2:$I945)),"" - "",TO_TEXT(SUM('Player Database'!$J$2:$J945)-SUM('Player Database'!$L$2:$L945)))"),"0 - 0") -> 0 - 0 | G123: =G122-COUNTIF(#REF!,"TRUE") -> 98
A125: Number of Active Heroes: | C125: =COUNTA($A4:$A120)-$C126-COUNTIFS($G4:$G120,30,$L4:$L120,"Maxed out") -> 1
A126: Number of Heroes Eliminated: | C126: =COUNTIF($L4:$L121,"Eliminated") -> 0

Sheet Villain Standings
A1: ARENA GAUNTLET LEAGUE: Marvel Super Heroes LEAGUE OF VILLAINS
A2: Week: | C2: =Quotas!B2 -> 3
A3: PLAYER NAME | B3: ARENA ID | C3: COUNTRY | D3: RANK | E3: Player Name & ID | F3: RECORD | G3: MATCHES PLAYED | H3: MATCHES <Min | I3: MATCHES <Max | J3: OMW% | K3: HERO SCORE | L3: MATCHES TO PLAY STATUS | M3: THIS WEEK | N3: OTHER INFO
A4: =IFERROR(__xludf.DUMMYFUNCTION("QUERY('Combined Standings'!A4:N175, ""Select A, B, C Where K < 0"")"),"#N/A") -> #N/A | D4: 1 | F4: =IFERROR(__xludf.DUMMYFUNCTION("QUERY('Combined Standings'!A4:N175, ""Select F, G, H, I, J, K, L, M, N Where K < 0"")"),"#N/A") -> #N/A
D5: =IF(A5="", "", D4+1)
D6: =IF(A6="", "", D5+1)
D7: =IF(A7="", "", D6+1)
D8: =IF(A8="", "", D7+1)
D9: =IF(A9="", "", D8+1)
D10: =IF(A10="", "", D9+1)
D11: =IF(A11="", "", D10+1)
D12: =IF(A12="", "", D11+1)
D13: =IF(A13="", "", D12+1)
D14: =IF(A14="", "", D13+1)
D15: =IF(A15="", "", D14+1)
D16: =IF(A16="", "", D15+1)
... D120: =IF(A120="", "", D119+1)
A121: ENTROPY | F121: =IFERROR(__xludf.DUMMYFUNCTION("CONCATENATE(TO_TEXT(SUM('Player Database'!$K:$K)),"" - 0"")"),"0 - 0") -> 0 - 0 | G121: =COUNTIF(Entropy!$C:$C,A121) -> 98
